Workbook

Sheet active
A1: component | B1: carrier | C1: category | D1: BASE | E1: NFS | F1: NPS | G1: NFS_NPS | H1: P1 | I1: M2045 | J1: NO_GAS | K1: BLEND
A2: Generator | B2: solar_pv_rooftop | C2: renewables | D2: =TRUE() -> TRUE | E2: =TRUE() -> TRUE | F2: =TRUE() -> TRUE | G2: =TRUE() -> TRUE | H2: =TRUE() -> TRUE | I2: =TRUE() -> TRUE | J2: =TRUE() -> TRUE | K2: =TRUE() -> TRUE
A3: Generator | B3: solar_pv | C3: renewables | D3: =TRUE() -> TRUE | E3: =TRUE() -> TRUE | F3: =TRUE() -> TRUE | G3: =TRUE() -> TRUE | H3: =TRUE() -> TRUE | I3: =TRUE() -> TRUE | J3: =TRUE() -> TRUE | K3: =TRUE() -> TRUE
A4: Generator | B4: solar_pv_low | C4: renewables | D4: =TRUE() -> TRUE | E4: =TRUE() -> TRUE | F4: =TRUE() -> TRUE | G4: =TRUE() -> TRUE | H4: =TRUE() -> TRUE | I4: =TRUE() -> TRUE | J4: =TRUE() -> TRUE | K4: =TRUE() -> TRUE
A5: Generator | B5: solar_csp | C5: renewables | D5: =TRUE() -> TRUE | E5: =TRUE() -> TRUE | F5: =TRUE() -> TRUE | G5: =TRUE() -> TRUE | H5: =TRUE() -> TRUE | I5: =TRUE() -> TRUE | J5: =TRUE() -> TRUE | K5: =TRUE() -> TRUE
A6: Generator | B6: wind | C6: renewables | D6: =TRUE() -> TRUE | E6: =TRUE() -> TRUE | F6: =TRUE() -> TRUE | G6: =TRUE() -> TRUE | H6: =TRUE() -> TRUE | I6: =TRUE() -> TRUE | J6: =TRUE() -> TRUE | K6: =TRUE() -> TRUE
A7: Generator | B7: wind_low | C7: renewables | D7: =TRUE() -> TRUE | E7: =TRUE() -> TRUE | F7: =TRUE() -> TRUE | G7: =TRUE() -> TRUE | H7: =TRUE() -> TRUE | I7: =TRUE() -> TRUE | J7: =TRUE() -> TRUE | K7: =TRUE() -> TRUE
A8: Generator | B8: ccgt_steam | C8: conventional | D8: =TRUE() -> TRUE | E8: =TRUE() -> TRUE | F8: =TRUE() -> TRUE | G8: =TRUE() -> TRUE | H8: =TRUE() -> TRUE | I8: =TRUE() -> TRUE | J8: =TRUE() -> TRUE | K8: =TRUE() -> TRUE
A9: Generator | B9: ocgt_gas | C9: conventional | D9: =TRUE() -> TRUE | E9: =TRUE() -> TRUE | F9: =TRUE() -> TRUE | G9: =TRUE() -> TRUE | H9: =TRUE() -> TRUE | I9: =TRUE() -> TRUE | J9: FALSE | K9: =TRUE() -> TRUE
A10: Generator | B10: ocgt_gas_h2_40 | C10: conventional | D10: =TRUE() -> TRUE | E10: =FALSE() -> FALSE | F10: =TRUE() -> TRUE | G10: =FALSE() -> FALSE | H10: =TRUE() -> TRUE | I10: =TRUE() -> TRUE | J10: FALSE | K10: =FALSE() -> FALSE
A11: Generator | B11: ocgt_gas_h2_45 | C11: conventional | D11: =TRUE() -> TRUE | E11: =FALSE() -> FALSE | F11: =TRUE() -> TRUE | G11: =FALSE() -> FALSE | H11: =TRUE() -> TRUE | I11: =TRUE() -> TRUE | J11: FALSE | K11: =FALSE() -> FALSE
A12: Generator | B12: ocgt_gas_h2_50 | C12: conventional | D12: =TRUE() -> TRUE | E12: =FALSE() -> FALSE | F12: =TRUE() -> TRUE | G12: =FALSE() -> FALSE | H12: =TRUE() -> TRUE | I12: FALSE | J12: FALSE | K12: =FALSE() -> FALSE
A13: Generator | B13: ocgt_gas_h2_55 | C13: conventional | D13: =TRUE() -> TRUE | E13: =FALSE() -> FALSE | F13: =TRUE() -> TRUE | G13: =FALSE() -> FALSE | H13: FALSE | I13: FALSE | J13: FALSE | K13: =FALSE() -> FALSE
A14: Generator | B14: ocgt_gas_h2_60 | C14: conventional | D14: =TRUE() -> TRUE | E14: =FALSE() -> FALSE | F14: =TRUE() -> TRUE | G14: =FALSE() -> FALSE | H14: =FALSE() -> FALSE | I14: FALSE | J14: FALSE | K14: =FALSE() -> FALSE
A15: Generator | B15: ocgt_diesel | C15: conventional | D15: =TRUE() -> TRUE | E15: =TRUE() -> TRUE | F15: =TRUE() -> TRUE | G15: =TRUE() -> TRUE | H15: =TRUE() -> TRUE | I15: =TRUE() -> TRUE | J15: =TRUE() -> TRUE | K15: =TRUE() -> TRUE
A16: Generator | B16: ocgt_diesel_emg | C16: conventional | D16: =FALSE() -> FALSE | E16: =FALSE() -> FALSE | F16: =FALSE() -> FALSE | G16: =FALSE() -> FALSE | H16: =FALSE() -> FALSE | I16: =FALSE() -> FALSE | J16: =FALSE() -> FALSE | K16: =FALSE() -> FALSE
A17: Generator | B17: ocgt_blend | C17: conventional | D17: =FALSE() -> FALSE | E17: =FALSE() -> FALSE | F17: =FALSE() -> FALSE | G17: =FALSE() -> FALSE | H17: =FALSE() -> FALSE | I17: =FALSE() -> FALSE | J17: =FALSE() -> FALSE | K17: TRUE
A18: Generator | B18: coal | C18: conventional | D18: =TRUE() -> TRUE | E18: =TRUE() -> TRUE | F18: =TRUE() -> TRUE | G18: =TRUE() -> TRUE | H18: =TRUE() -> TRUE | I18: =TRUE() -> TRUE | J18: =TRUE() -> TRUE | K18: =TRUE() -> TRUE
A19: Generator | B19: nuclear | C19: conventional | D19: =TRUE() -> TRUE | E19: =TRUE() -> TRUE | F19: =TRUE() -> TRUE | G19: =TRUE() -> TRUE | H19: =TRUE() -> TRUE | I19: =TRUE() -> TRUE | J19: =TRUE() -> TRUE | K19: =TRUE() -> TRUE
A20: StorageUnit | B20: phs | C20: storage | D20: =TRUE() -> TRUE | E20: =TRUE() -> TRUE | F20: FALSE | G20: =TRUE() -> TRUE | H20: =TRUE() -> TRUE | I20: =TRUE() -> TRUE | J20: =TRUE() -> TRUE | K20: =TRUE() -> TRUE
A21: StorageUnit | B21: battery_1h | C21: storage | D21: =TRUE() -> TRUE | E21: =TRUE() -> TRUE | F21: =TRUE() -> TRUE | G21: =TRUE() -> TRUE | H21: =TRUE() -> TRUE | I21: =TRUE() -> TRUE | J21: =TRUE() -> TRUE | K21: =TRUE() -> TRUE
A22: StorageUnit | B22: battery_3h | C22: storage | D22: =FALSE() -> FALSE | E22: =FALSE() -> FALSE | F22: =FALSE() -> FALSE | G22: =FALSE() -> FALSE | H22: =FALSE() -> FALSE | I22: =FALSE() -> FALSE | J22: =FALSE() -> FALSE | K22: =FALSE() -> FALSE
A23: StorageUnit | B23: battery_4h | C23: storage | D23: =TRUE() -> TRUE | E23: =TRUE() -> TRUE | F23: =TRUE() -> TRUE | G23: =TRUE() -> TRUE | H23: =TRUE() -> TRUE | I23: =TRUE() -> TRUE | J23: =TRUE() -> TRUE | K23: =TRUE() -> TRUE
A24: StorageUnit | B24: battery_8h | C24: storage | D24: =TRUE() -> TRUE | E24: =TRUE() -> TRUE | F24: =TRUE() -> TRUE | G24: =TRUE() -> TRUE | H24: =TRUE() -> TRUE | I24: =TRUE() -> TRUE | J24: =TRUE() -> TRUE | K24: =TRUE() -> TRUE

Sheet parameter_mapping
A1: scenario | B1: carrier | C1: FOM | D1: overnight_capex | E1: total_vs_overnight_capex_ratio | F1: VOM | G1: lifetime | H1: max_hours | I1: heat_rate | J1: efficiency | K1: build_phase_in | L1: ramp_limit_up | M1: ramp_limit_down | N1: committable | O1: ramp_limit_start_up | P1: ramp_limit_shut_down | Q1: min_stable_level | R1: min_up_time | S1: min_down_time | T1: start_up_cost | U1: shut_down_cost | V1: discount_rate
A2: HIGH_PMR1 | B2: battery_1h | C2: default | D2: HIGH_PMR1 | E2: default | F2: default | G2: default | H2: default | J2: default | K2: overnight
A3: HIGH_PMR1 | B3: battery_4h | C3: default | D3: HIGH_PMR1 | E3: default | F3: default | G3: default | H3: default | J3: default | K3: overnight
A4: HIGH_PMR1 | B4: battery_8h | C4: default | D4: HIGH_PMR1 | E4: default | F4: default | G4: default | H4: default | J4: default | K4: overnight
A5: HIGH_PMR1 | B5: phs | C5: default | D5: default | E5: WACC_124 | F5: default | G5: default | H5: default | J5: default | K5: overnight
A6: HIGH_PMR1 | B6: coal | C6: default | D6: default | E6: WACC_124 | F6: default | G6: default | I6: default | J6: default | K6: overnight | L6: default | M6: default | N6: default | O6: default | P6: default | Q6: default | R6: default | S6: default | T6: default | U6: default
A7: HIGH_PMR1 | B7: nuclear | C7: default | D7: default | E7: WACC_124 | F7: default | G7: default | I7: default | J7: default | K7: overnight | L7: default | M7: default | N7: default | O7: default | P7: default | Q7: default | R7: default | S7: default | T7: default | U7: default
A8: HIGH_PMR1 | B8: ocgt_diesel | C8: default | D8: default | E8: WACC_124 | F8: default | G8: default | I8: default | J8: default | K8: overnight | N8: default | Q8: default
A9: HIGH_PMR1 | B9: ocgt_diesel_emg | C9: default | D9: default | E9: WACC_124 | F9: default | G9: default | I9: default | J9: default | K9: overnight | N9: default | Q9: default
A10: HIGH_PMR1 | B10: ocgt_gas | C10: default | D10: default | E10: WACC_124 | F10: default | G10: default | I10: default | J10: default | K10: overnight | N10: default | Q10: default
A11: HIGH_PMR1 | B11: ocgt_gas_h2_40 | C11: default | D11: default | E11: WACC_124 | F11: default | G11: default | I11: default | J11: default | K11: overnight | N11: default | Q11: default
A12: HIGH_PMR1 | B12: ocgt_gas_h2_45 | C12: default | D12: default | E12: WACC_124 | F12: default | G12: default | I12: default | J12: default | K12: overnight | N12: default | Q12: default
A13: HIGH_PMR1 | B13: ocgt_gas_h2_50 | C13: default | D13: default | E13: WACC_124 | F13: default | G13: default | I13: default | J13: default | K13: overnight | N13: default | Q13: default
A14: HIGH_PMR1 | B14: ocgt_gas_h2_55 | C14: default | D14: default | E14: WACC_124 | F14: default | G14: default | I14: default | J14: default | K14: overnight | N14: default | Q14: default
A15: HIGH_PMR1 | B15: ocgt_gas_h2_60 | C15: default | D15: default | E15: WACC_124 | F15: default | G15: default | I15: default | J15: default | K15: overnight | N15: default | Q15: default
A16: HIGH_PMR1 | B16: ccgt_steam | C16: default | D16: default | E16: WACC_124 | F16: default | G16: default | I16: default | J16: default | K16: overnight | L16: default | M16: default | N16: default | O16: default | P16: default | Q16: default | R16: default | S16: default | T16: default | U16: default
A17: HIGH_PMR1 | B17: solar_pv | C17: default | D17: HIGH_PMR1 | E17: WACC_124 | F17: default | G17: default | K17: overnight
A18: HIGH_PMR1 | B18: solar_pv_low | C18: default | D18: HIGH_PMR1 | E18: WACC_124 | F18: default | G18: default | K18: overnight
A19: HIGH_PMR1 | B19: solar_pv_rooftop | C19: default | D19: HIGH_PMR1 | E19: WACC_124 | F19: default | G19: default | K19: overnight
A20: HIGH_PMR1 | B20: solar_csp | C20: default | D20: default | E20: WACC_124 | F20: default | G20: default | K20: overnight
A21: HIGH_PMR1 | B21: wind | C21: default | D21: HIGH_PMR1 | E21: WACC_124 | F21: default | G21: default | K21: overnight
A22: HIGH_PMR1 | B22: wind_low | C22: default | D22: HIGH_PMR1 | E22: WACC_124 | F22: default | G22: default | K22: overnight
A23: BASE_PMR1 | B23: battery_1h | C23: default | D23: BASE_PMR1 | E23: default | F23: default | G23: default | H23: default | J23: default | K23: overnight
A24: BASE_PMR1 | B24: battery_4h | C24: default | D24: BASE_PMR1 | E24: default | F24: default | G24: default | H24: default | J24: default | K24: overnight
A25: BASE_PMR1 | B25: battery_8h | C25: default | D25: BASE_PMR1 | E25: default | F25: default | G25: default | H25: default | J25: default | K25: overnight
A26: BASE_PMR1 | B26: phs | C26: default | D26: default | E26: WACC_095 | F26: default | G26: default | H26: default | J26: default | K26: overnight
A27: BASE_PMR1 | B27: coal | C27: default | D27: default | E27: WACC_095 | F27: default | G27: default | I27: default | J27: default | K27: overnight | L27: default | M27: default | N27: default | O27: default | P27: default | Q27: default | R27: default | S27: default | T27: default | U27: default
A28: BASE_PMR1 | B28: nuclear | C28: default | D28: default | E28: WACC_095 | F28: default | G28: default | I28: default | J28: default | K28: overnight | L28: default | M28: default | N28: default | O28: default | P28: default | Q28: default | R28: default | S28: default | T28: default | U28: default
A29: BASE_PMR1 | B29: ocgt_diesel | C29: default | D29: default | E29: WACC_095 | F29: default | G29: default | I29: default | J29: default | K29: overnight | N29: default | Q29: default
A30: BASE_PMR1 | B30: ocgt_diesel_emg | C30: default | D30: default | E30: WACC_095 | F30: default | G30: default | I30: default | J30: default | K30: overnight | N30: default | Q30: default
A31: BASE_PMR1 | B31: ocgt_gas | C31: default | D31: default | E31: WACC_095 | F31: default | G31: default | I31: default | J31: default | K31: overnight | N31: default | Q31: default
A32: BASE_PMR1 | B32: ocgt_gas_h2_40 | C32: default | D32: default | E32: WACC_095 | F32: default | G32: default | I32: default | J32: default | K32: overnight | N32: default | Q32: default
A33: BASE_PMR1 | B33: ocgt_gas_h2_45 | C33: default | D33: default | E33: WACC_095 | F33: default | G33: default | I33: default | J33: default | K33: overnight | N33: default | Q33: default
A34: BASE_PMR1 | B34: ocgt_gas_h2_50 | C34: default | D34: default | E34: WACC_095 | F34: default | G34: default | I34: default | J34: default | K34: overnight | N34: default | Q34: default
A35: BASE_PMR1 | B35: ocgt_gas_h2_55 | C35: default | D35: default | E35: WACC_095 | F35: default | G35: default | I35: default | J35: default | K35: overnight | N35: default | Q35: default
A36: BASE_PMR1 | B36: ocgt_gas_h2_60 | C36: default | D36: default | E36: WACC_095 | F36: default | G36: default | I36: default | J36: default | K36: overnight | N36: default | Q36: default
A37: BASE_PMR1 | B37: ccgt_steam | C37: default | D37: default | E37: WACC_095 | F37: default | G37: default | I37: default | J37: default | K37: overnight | L37: default | M37: default | N37: default | O37: default | P37: default | Q37: default | R37: default | S37: default | T37: default | U37: default
A38: BASE_PMR1 | B38: solar_pv | C38: default | D38: BASE_PMR1 | E38: WACC_095 | F38: default | G38: default | K38: overnight
A39: BASE_PMR1 | B39: solar_pv_low | C39: default | D39: BASE_PMR1 | E39: WACC_095 | F39: default | G39: default | K39: overnight
A40: BASE_PMR1 | B40: solar_pv_rooftop | C40: default | D40: BASE_PMR1 | E40: WACC_095 | F40: default | G40: default | K40: overnight
...

Sheet parameters
A1: scenario | B1: carrier | C1: parameter | D1: units | E1: 2024 | F1: 2025 | G1: 2026 | H1: 2027 | I1: 2028 | J1: 2029 | K1: 2030 | L1: 2031 | M1: 2032 | N1: 2033 | O1: 2034 | P1: 2035 | Q1: 2036 | R1: 2037 | S1: 2038 | T1: 2039 | U1: 2040 | V1: 2041 | W1: 2042 | X1: 2043 | Y1: 2044 | Z1: 2045 | AA1: 2046 | AB1: 2047 | AC1: 2048 | AD1: 2049 | AE1: 2050 | AF1: =AE1+1 -> 2051 | AG1: =AF1+1 -> 2052 | AH1: =AG1+1 -> 2053 | AI1: =AH1+1 -> 2054 | AJ1: =AI1+1 -> 2055 | AK1: =AJ1+1 -> 2056 | AL1: =AK1+1 -> 2057 | AM1: =AL1+1 -> 2058 | ... AO1: =AN1+1 -> 2060 | AP1: source
A2: default | B2: coal | C2: carrier_emissions | D2: tCO2/MWht | E2: 0.346 | F2: =E2 -> 0.346 | G2: =F2 -> 0.346 | H2: =G2 -> 0.346 | I2: =H2 -> 0.346 | J2: =I2 -> 0.346 | K2: =J2 -> 0.346 | L2: =K2 -> 0.346 | M2: =L2 -> 0.346 | ... AO2: =AN2 -> 0.346
A3: default | B3: sasol_coal | C3: carrier_emissions | D3: tCO2/MWht | E3: 0.346 | F3: =F2 -> 0.346 | G3: =G2 -> 0.346 | H3: =H2 -> 0.346 | I3: =I2 -> 0.346 | J3: =J2 -> 0.346 | K3: =K2 -> 0.346 | L3: =L2 -> 0.346 | M3: =M2 -> 0.346 | ... AE3: =AE2 -> 0.346 | AF3: =AE3 -> 0.346 | AG3: =AF3 -> 0.346 | AH3: =AG3 -> 0.346 | AI3: =AH3 -> 0.346 | AJ3: =AI3 -> 0.346 | AK3: =AJ3 -> 0.346 | AL3: =AK3 -> 0.346 | AM3: =AL3 -> 0.346 | ... AO3: =AN3 -> 0.346
A4: default | B4: ocgt_diesel | C4: carrier_emissions | D4: tCO2/MWht | E4: 0.267 | F4: 0.267 | G4: 0.267 | H4: 0.267 | I4: 0.267 | J4: 0.267 | K4: 0.267 | L4: 0.267 | M4: 0.267 | N4: 0.267 | O4: 0.267 | P4: 0.267 | Q4: 0.267 | R4: 0.267 | S4: 0.267 | T4: 0.267 | U4: 0 | V4: 0 | W4: 0 | X4: 0 | Y4: 0 | Z4: 0 | AA4: 0 | AB4: 0 | AC4: 0 | AD4: 0 | AE4: 0 | AF4: =AE4 -> 0 | AG4: =AF4 -> 0 | AH4: =AG4 -> 0 | AI4: =AH4 -> 0 | AJ4: =AI4 -> 0 | AK4: =AJ4 -> 0 | AL4: =AK4 -> 0 | AM4: =AL4 -> 0 | ... AO4: =AN4 -> 0
A5: default | B5: ocgt_diesel_emg | C5: carrier_emissions | D5: tCO2/MWht | E5: 0.267 | F5: 0.267 | G5: 0.267 | H5: 0.267 | I5: 0.267 | J5: 0.267 | K5: 0.267 | L5: 0.267 | M5: 0.267 | N5: 0.267 | O5: 0.267 | P5: 0.267 | Q5: 0.267 | R5: 0.267 | S5: 0.267 | T5: 0.267 | U5: 0 | V5: 0 | W5: 0 | X5: 0 | Y5: 0 | Z5: 0 | AA5: 0 | AB5: 0 | AC5: 0 | AD5: 0 | AE5: 0 | AF5: =AE5 -> 0 | AG5: =AF5 -> 0 | AH5: =AG5 -> 0 | AI5: =AH5 -> 0 | AJ5: =AI5 -> 0 | AK5: =AJ5 -> 0 | AL5: =AK5 -> 0 | AM5: =AL5 -> 0 | ... AO5: =AN5 -> 0
A6: default | B6: ocgt_avf | C6: carrier_emissions | D6: tCO2/MWht | E6: 0.267 | F6: 0.267 | G6: 0.267 | H6: 0.267 | I6: 0.267 | J6: 0.267 | K6: 0.267 | L6: 0.267 | M6: 0.267 | N6: 0.267 | O6: 0.267 | P6: 0.267 | Q6: 0.267 | R6: 0.267 | S6: 0.267 | T6: 0.267 | U6: =T6 -> 0.267 | V6: =U6 -> 0.267 | W6: =V6 -> 0.267 | X6: =W6 -> 0.267 | Y6: =X6 -> 0.267 | Z6: =Y6 -> 0.267 | AA6: =Z6 -> 0.267 | AB6: =AA6 -> 0.267 | ... AO6: =AN6 -> 0.267
A7: default | B7: ocgt_gas | C7: carrier_emissions | D7: tCO2/MWht | E7: 0.249 | F7: 0.249 | G7: 0.249 | H7: 0.249 | I7: 0.249 | J7: 0.249 | K7: 0.249 | L7: 0.249 | M7: 0.249 | N7: 0.249 | O7: 0.249 | P7: 0.249 | Q7: 0.249 | R7: 0.249 | S7: 0.249 | T7: 0.249 | U7: 0.249 | V7: 0.249 | W7: 0.249 | X7: 0.249 | Y7: 0.249 | Z7: 0.249 | AA7: 0.249 | AB7: 0.249 | AC7: 0.249 | AD7: 0.249 | AE7: 0.249 | AF7: =AE7 -> 0.249 | AG7: =AF7 -> 0.249 | AH7: =AG7 -> 0.249 | AI7: =AH7 -> 0.249 | AJ7: =AI7 -> 0.249 | AK7: =AJ7 -> 0.249 | AL7: =AK7 -> 0.249 | AM7: =AL7 -> 0.249 | ... AO7: =AN7 -> 0.249
A8: default | B8: ocgt_gas_h2_40 | C8: carrier_emissions | D8: tCO2/MWht | E8: 0.249 | F8: 0.249 | G8: 0.249 | H8: 0.249 | I8: 0.249 | J8: 0.249 | K8: 0.249 | L8: 0.249 | M8: 0.249 | N8: 0.249 | O8: 0.249 | P8: 0.249 | Q8: 0.249 | R8: 0.249 | S8: 0.249 | T8: 0.249 | U8: 0 | V8: 0 | W8: 0 | X8: 0 | Y8: 0 | Z8: 0 | AA8: 0 | AB8: 0 | AC8: 0 | AD8: 0 | AE8: 0 | AF8: =AE8 -> 0 | AG8: =AF8 -> 0 | AH8: =AG8 -> 0 | AI8: =AH8 -> 0 | AJ8: =AI8 -> 0 | AK8: =AJ8 -> 0 | AL8: =AK8 -> 0 | AM8: =AL8 -> 0 | ... AO8: =AN8 -> 0
A9: default | B9: ocgt_gas_h2_45 | C9: carrier_emissions | D9: tCO2/MWht | E9: 0.249 | F9: 0.249 | G9: 0.249 | H9: 0.249 | I9: 0.249 | J9: 0.249 | K9: 0.249 | L9: 0.249 | M9: 0.249 | N9: 0.249 | O9: 0.249 | P9: 0.249 | Q9: 0.249 | R9: 0.249 | S9: 0.249 | T9: 0.249 | U9: 0.249 | V9: 0.249 | W9: 0.249 | X9: 0.249 | Y9: 0.249 | Z9: 0 | AA9: 0 | AB9: 0 | AC9: 0 | AD9: 0 | AE9: 0 | AF9: =AE9 -> 0 | AG9: =AF9 -> 0 | AH9: =AG9 -> 0 | AI9: =AH9 -> 0 | AJ9: =AI9 -> 0 | AK9: =AJ9 -> 0 | AL9: =AK9 -> 0 | AM9: =AL9 -> 0 | ... AO9: =AN9 -> 0
A10: default | B10: ocgt_gas_h2_50 | C10: carrier_emissions | D10: tCO2/MWht | E10: 0.249 | F10: 0.249 | G10: 0.249 | H10: 0.249 | I10: 0.249 | J10: 0.249 | K10: 0.249 | L10: 0.249 | M10: 0.249 | N10: 0.249 | O10: 0.249 | P10: 0.249 | Q10: 0.249 | R10: 0.249 | S10: 0.249 | T10: 0.249 | U10: 0.249 | V10: 0.249 | W10: 0.249 | X10: 0.249 | Y10: 0.249 | Z10: 0.249 | AA10: 0.249 | AB10: 0.249 | AC10: 0.249 | AD10: 0.249 | AE10: 0 | AF10: =AE10 -> 0 | AG10: =AF10 -> 0 | AH10: =AG10 -> 0 | AI10: =AH10 -> 0 | AJ10: =AI10 -> 0 | AK10: =AJ10 -> 0 | AL10: =AK10 -> 0 | AM10: =AL10 -> 0 | ... AO10: =AN10 -> 0
A11: default | B11: ocgt_gas_h2_55 | C11: carrier_emissions | D11: tCO2/MWht | E11: 0.249 | F11: 0.249 | G11: 0.249 | H11: 0.249 | I11: 0.249 | J11: 0.249 | K11: 0.249 | L11: 0.249 | M11: 0.249 | N11: 0.249 | O11: 0.249 | P11: 0.249 | Q11: 0.249 | R11: 0.249 | S11: 0.249 | T11: 0.249 | U11: 0.249 | V11: 0.249 | W11: 0.249 | X11: 0.249 | Y11: 0.249 | Z11: 0.249 | AA11: 0.249 | AB11: 0.249 | AC11: 0.249 | AD11: 0.249 | AE11: 0.249 | AF11: 0.249 | AG11: 0.249 | AH11: 0.249 | AI11: 0.249 | AJ11: 0 | AK11: 0 | AL11: 0 | AM11: 0 | AN11: 0 | AO11: 0
A12: default | B12: ocgt_gas_h2_60 | C12: carrier_emissions | D12: tCO2/MWht | E12: 0.249 | F12: 0.249 | G12: 0.249 | H12: 0.249 | I12: 0.249 | J12: 0.249 | K12: 0.249 | L12: 0.249 | M12: 0.249 | N12: 0.249 | O12: 0.249 | P12: 0.249 | Q12: 0.249 | R12: 0.249 | S12: 0.249 | T12: 0.249 | U12: 0.249 | V12: 0.249 | W12: 0.249 | X12: 0.249 | Y12: 0.249 | Z12: 0.249 | AA12: 0.249 | AB12: 0.249 | AC12: 0.249 | AD12: 0.249 | AE12: 0.249 | AF12: 0.249 | AG12: 0.249 | AH12: 0.249 | AI12: 0.249 | AJ12: 0.249 | AK12: 0.249 | AL12: 0.249 | AM12: 0.249 | AN12: 0.249 | AO12: 0
A13: default | B13: sasol_gas | C13: carrier_emissions | D13: tCO2/MWht | E13: 0.249 | F13: 0.249 | G13: 0.249 | H13: 0.249 | I13: 0.249 | J13: 0.249 | K13: 0.249 | L13: 0.249 | M13: 0.249 | N13: 0.249 | O13: 0.249 | P13: 0.249 | Q13: 0.249 | R13: 0.249 | S13: 0.249 | T13: 0.249 | U13: =T13 -> 0.249 | V13: =U13 -> 0.249 | W13: =V13 -> 0.249 | X13: =W13 -> 0.249 | Y13: =X13 -> 0.249 | Z13: =Y13 -> 0.249 | AA13: =Z13 -> 0.249 | AB13: =AA13 -> 0.249 | ... AN13: =AM13 -> 0.249 | AO13: 0.249
A14: default | B14: coal | C14: output_emissions | D14: tCO2/MWh | E14: 0.93958222 | F14: =F2/F55 -> 0.93958222 | G14: =G2/G55 -> 0.93958222 | H14: =H2/H55 -> 0.93958222 | I14: =I2/I55 -> 0.93958222 | J14: =J2/J55 -> 0.93958222 | K14: =K2/K55 -> 0.93958222 | L14: =L2/L55 -> 0.93958222 | M14: =M2/M55 -> 0.93958222 | ... AE14: =AE2/AE55 -> 0.93958222 | AF14: =AE14 -> 0.93958222 | AG14: =AF14 -> 0.93958222 | AH14: =AG14 -> 0.93958222 | AI14: =AH14 -> 0.93958222 | AJ14: =AI14 -> 0.93958222 | AK14: =AJ14 -> 0.93958222 | AL14: =AK14 -> 0.93958222 | AM14: =AL14 -> 0.93958222 | ... AO14: =AN14 -> 0.93958222
A15: default | B15: sasol_coal | C15: output_emissions | D15: tCO2/MWh | E15: 0.93958222 | F15: =F14 -> 0.93958222 | G15: =G14 -> 0.93958222 | H15: =H14 -> 0.93958222 | I15: =I14 -> 0.93958222 | J15: =J14 -> 0.93958222 | K15: =K14 -> 0.93958222 | L15: =L14 -> 0.93958222 | M15: =M14 -> 0.93958222 | ... AE15: =AE14 -> 0.93958222 | AF15: =AE15 -> 0.93958222 | AG15: =AF15 -> 0.93958222 | AH15: =AG15 -> 0.93958222 | AI15: =AH15 -> 0.93958222 | AJ15: =AI15 -> 0.93958222 | AK15: =AJ15 -> 0.93958222 | AL15: =AK15 -> 0.93958222 | AM15: =AL15 -> 0.93958222 | ... AO15: =AN15 -> 0.93958222
A16: default | B16: ocgt_diesel | C16: output_emissions | D16: tCO2/MWh | E16: =E4/E57 -> 0.7010975 | F16: =F4/F57 -> 0.7010975 | G16: =G4/G57 -> 0.7010975 | H16: =H4/H57 -> 0.7010975 | I16: =I4/I57 -> 0.7010975 | J16: =J4/J57 -> 0.7010975 | K16: =K4/K57 -> 0.7010975 | L16: =L4/L57 -> 0.7010975 | ... AO16: =AO4/AO57 -> 0
A17: default | B17: ocgt_diesel_emg | C17: output_emissions | D17: tCO2/MWh | E17: =E5/E58 -> 0.7010975 | F17: =F5/F58 -> 0.7010975 | G17: =G5/G58 -> 0.7010975 | H17: =H5/H58 -> 0.7010975 | I17: =I5/I58 -> 0.7010975 | J17: =J5/J58 -> 0.7010975 | K17: =K5/K58 -> 0.7010975 | L17: =L5/L58 -> 0.7010975 | ... AO17: =AO5/AO58 -> 0
A18: default | B18: ocgt_avf | C18: output_emissions | D18: tCO2/MWh | E18: =E6/E59 -> 0.7010975 | F18: =F6/F59 -> 0.7010975 | G18: =G6/G59 -> 0.7010975 | H18: =H6/H59 -> 0.7010975 | I18: =I6/I59 -> 0.7010975 | J18: =J6/J59 -> 0.7010975 | K18: =K6/K59 -> 0.7010975 | L18: =L6/L59 -> 0.7010975 | ... AO18: =AO6/AO59 -> 0.7010975
A19: default | B19: ocgt_gas | C19: output_emissions | D19: tCO2/MWh | E19: =E7/E60 -> 0.6538325 | F19: =F7/F60 -> 0.6538325 | G19: =G7/G60 -> 0.6538325 | H19: =H7/H60 -> 0.6538325 | I19: =I7/I60 -> 0.6538325 | J19: =J7/J60 -> 0.6538325 | K19: =K7/K60 -> 0.6538325 | L19: =L7/L60 -> 0.6538325 | ... AO19: =AO7/AO60 -> 0.6538325
A20: default | B20: ocgt_gas_h2_40 | C20: output_emissions | D20: tCO2/MWh | E20: =E8/E61 -> 0.6538325 | F20: =F8/F61 -> 0.6538325 | G20: =G8/G61 -> 0.6538325 | H20: =H8/H61 -> 0.6538325 | I20: =I8/I61 -> 0.6538325 | J20: =J8/J61 -> 0.6538325 | K20: =K8/K61 -> 0.6538325 | L20: =L8/L61 -> 0.6538325 | ... AO20: =AO8/AO61 -> 0
A21: default | B21: ocgt_gas_h2_45 | C21: output_emissions | D21: tCO2/MWh | E21: =E9/E62 -> 0.6538325 | F21: =F9/F62 -> 0.6538325 | G21: =G9/G62 -> 0.6538325 | H21: =H9/H62 -> 0.6538325 | I21: =I9/I62 -> 0.6538325 | J21: =J9/J62 -> 0.6538325 | K21: =K9/K62 -> 0.6538325 | L21: =L9/L62 -> 0.6538325 | ... AO21: =AO9/AO62 -> 0
A22: default | B22: ocgt_gas_h2_50 | C22: output_emissions | D22: tCO2/MWh | E22: =E10/E63 -> 0.6538325 | F22: =F10/F63 -> 0.6538325 | G22: =G10/G63 -> 0.6538325 | H22: =H10/H63 -> 0.6538325 | I22: =I10/I63 -> 0.6538325 | J22: =J10/J63 -> 0.6538325 | K22: =K10/K63 -> 0.6538325 | L22: =L10/L63 -> 0.6538325 | ... AO22: =AO10/AO63 -> 0
A23: default | B23: ocgt_gas_h2_55 | C23: output_emissions | D23: tCO2/MWh | E23: =E11/E64 -> 0.6538325 | F23: =F11/F64 -> 0.6538325 | G23: =G11/G64 -> 0.6538325 | H23: =H11/H64 -> 0.6538325 | I23: =I11/I64 -> 0.6538325 | J23: =J11/J64 -> 0.6538325 | K23: =K11/K64 -> 0.6538325 | L23: =L11/L64 -> 0.6538325 | ... AO23: =AO11/AO64 -> 0
A24: default | B24: ocgt_gas_h2_60 | C24: output_emissions | D24: tCO2/MWh | E24: =E12/E66 -> 0.31923077 | F24: =F12/F66 -> 0.31923077 | G24: =G12/G66 -> 0.31923077 | H24: =H12/H66 -> 0.31923077 | I24: =I12/I66 -> 0.31923077 | J24: =J12/J66 -> 0.31923077 | K24: =K12/K66 -> 0.31923077 | L24: =L12/L66 -> 0.31923077 | ... AO24: =AO12/AO66 -> 0
A25: default | B25: sasol_gas | C25: output_emissions | D25: tCO2/MWh | E25: =E13/E67 -> 0.498 | F25: =F13/F67 -> 0.498 | G25: =G13/G67 -> 0.498 | H25: =H13/H67 -> 0.498 | I25: =I13/I67 -> 0.498 | J25: =J13/J67 -> 0.498 | K25: =K13/K67 -> 0.498 | L25: =L13/L67 -> 0.498 | ... AO25: =AO13/AO67 -> 0.498
A26: default | B26: solar_pv | C26: discount_rate | D26: per unit | E26: 0.082 | F26: 0.082 | G26: 0.082 | H26: 0.082 | I26: 0.082 | J26: 0.082 | K26: 0.082 | L26: 0.082 | M26: 0.082 | N26: 0.082 | O26: 0.082 | P26: 0.082 | Q26: 0.082 | R26: 0.082 | S26: 0.082 | T26: 0.082 | U26: 0.082 | V26: 0.082 | W26: 0.082 | X26: 0.082 | Y26: 0.082 | Z26: 0.082 | AA26: 0.082 | AB26: 0.082 | AC26: 0.082 | AD26: 0.082 | AE26: 0.082 | AF26: =AE26 -> 0.082 | AG26: =AF26 -> 0.082 | AH26: =AG26 -> 0.082 | AI26: =AH26 -> 0.082 | AJ26: =AI26 -> 0.082 | AK26: =AJ26 -> 0.082 | AL26: =AK26 -> 0.082 | AM26: =AL26 -> 0.082 | ... AO26: =AN26 -> 0.082
A27: default | B27: solar_pv_rooftop | C27: discount_rate | D27: per unit | E27: 0.082 | F27: 0.082 | G27: 0.082 | H27: 0.082 | I27: 0.082 | J27: 0.082 | K27: 0.082 | L27: 0.082 | M27: 0.082 | N27: 0.082 | O27: 0.082 | P27: 0.082 | Q27: 0.082 | R27: 0.082 | S27: 0.082 | T27: 0.082 | U27: 0.082 | V27: 0.082 | W27: 0.082 | X27: 0.082 | Y27: 0.082 | Z27: 0.082 | AA27: 0.082 | AB27: 0.082 | AC27: 0.082 | AD27: 0.082 | AE27: 0.082 | AF27: =AE27 -> 0.082 | AG27: =AF27 -> 0.082 | AH27: =AG27 -> 0.082 | AI27: =AH27 -> 0.082 | AJ27: =AI27 -> 0.082 | AK27: =AJ27 -> 0.082 | AL27: =AK27 -> 0.082 | AM27: =AL27 -> 0.082 | ... AO27: =AN27 -> 0.082
A28: default | B28: solar_pv_low | C28: discount_rate | D28: per unit | E28: 0.082 | F28: 0.082 | G28: 0.082 | H28: 0.082 | I28: 0.082 | J28: 0.082 | K28: 0.082 | L28: 0.082 | M28: 0.082 | N28: 0.082 | O28: 0.082 | P28: 0.082 | Q28: 0.082 | R28: 0.082 | S28: 0.082 | T28: 0.082 | U28: 0.082 | V28: 0.082 | W28: 0.082 | X28: 0.082 | Y28: 0.082 | Z28: 0.082 | AA28: 0.082 | AB28: 0.082 | AC28: 0.082 | AD28: 0.082 | AE28: 0.082 | AF28: =AE28 -> 0.082 | AG28: =AF28 -> 0.082 | AH28: =AG28 -> 0.082 | AI28: =AH28 -> 0.082 | AJ28: =AI28 -> 0.082 | AK28: =AJ28 -> 0.082 | AL28: =AK28 -> 0.082 | AM28: =AL28 -> 0.082 | ... AO28: =AN28 -> 0.082
A29: default | B29: wind | C29: discount_rate | D29: per unit | E29: 0.082 | F29: 0.082 | G29: 0.082 | H29: 0.082 | I29: 0.082 | J29: 0.082 | K29: 0.082 | L29: 0.082 | M29: 0.082 | N29: 0.082 | O29: 0.082 | P29: 0.082 | Q29: 0.082 | R29: 0.082 | S29: 0.082 | T29: 0.082 | U29: 0.082 | V29: 0.082 | W29: 0.082 | X29: 0.082 | Y29: 0.082 | Z29: 0.082 | AA29: 0.082 | AB29: 0.082 | AC29: 0.082 | AD29: 0.082 | AE29: 0.082 | AF29: =AE29 -> 0.082 | AG29: =AF29 -> 0.082 | AH29: =AG29 -> 0.082 | AI29: =AH29 -> 0.082 | AJ29: =AI29 -> 0.082 | AK29: =AJ29 -> 0.082 | AL29: =AK29 -> 0.082 | AM29: =AL29 -> 0.082 | ... AO29: =AN29 -> 0.082
A30: default | B30: wind_low | C30: discount_rate | D30: per unit | E30: 0.082 | F30: 0.082 | G30: 0.082 | H30: 0.082 | I30: 0.082 | J30: 0.082 | K30: 0.082 | L30: 0.082 | M30: 0.082 | N30: 0.082 | O30: 0.082 | P30: 0.082 | Q30: 0.082 | R30: 0.082 | S30: 0.082 | T30: 0.082 | U30: 0.082 | V30: 0.082 | W30: 0.082 | X30: 0.082 | Y30: 0.082 | Z30: 0.082 | AA30: 0.082 | AB30: 0.082 | AC30: 0.082 | AD30: 0.082 | AE30: 0.082 | AF30: =AE30 -> 0.082 | AG30: =AF30 -> 0.082 | AH30: =AG30 -> 0.082 | AI30: =AH30 -> 0.082 | AJ30: =AI30 -> 0.082 | AK30: =AJ30 -> 0.082 | AL30: =AK30 -> 0.082 | AM30: =AL30 -> 0.082 | ... AO30: =AN30 -> 0.082
A31: default | B31: biomass_forestry | C31: heat_rate | D31: GJ/MWh | E31: 14.132 | F31: 14.132 | G31: 14.132 | H31: 14.132 | I31: 14.132 | J31: 14.132 | K31: 14.132 | L31: 14.132 | M31: 14.132 | N31: 14.132 | O31: 14.132 | P31: 14.132 | Q31: 14.132 | R31: 14.132 | S31: 14.132 | T31: 14.132 | U31: 14.132 | V31: 14.132 | W31: 14.132 | X31: 14.132 | Y31: 14.132 | Z31: 14.132 | AA31: 14.132 | AB31: 14.132 | AC31: 14.132 | AD31: 14.132 | AE31: 14.132 | AF31: =AE31 -> 14.132 | AG31: =AF31 -> 14.132 | AH31: =AG31 -> 14.132 | AI31: =AH31 -> 14.132 | AJ31: =AI31 -> 14.132 | AK31: =AJ31 -> 14.132 | AL31: =AK31 -> 14.132 | AM31: =AL31 -> 14.132 | ... AO31: =AN31 -> 14.132
A32: default | B32: biomass_landfill_gas | C32: heat_rate | D32: GJ/MWh | E32: 12.302 | F32: 12.302 | G32: 12.302 | H32: 12.302 | I32: 12.302 | J32: 12.302 | K32: 12.302 | L32: 12.302 | M32: 12.302 | N32: 12.302 | O32: 12.302 | P32: 12.302 | Q32: 12.302 | R32: 12.302 | S32: 12.302 | T32: 12.302 | U32: 12.302 | V32: 12.302 | W32: 12.302 | X32: 12.302 | Y32: 12.302 | Z32: 12.302 | AA32: 12.302 | AB32: 12.302 | AC32: 12.302 | AD32: 12.302 | AE32: 12.302 | AF32: =AE32 -> 12.302 | AG32: =AF32 -> 12.302 | AH32: =AG32 -> 12.302 | AI32: =AH32 -> 12.302 | AJ32: =AI32 -> 12.302 | AK32: =AJ32 -> 12.302 | AL32: =AK32 -> 12.302 | AM32: =AL32 -> 12.302 | ... AO32: =AN32 -> 12.302
A33: default | B33: biomass_biogas | C33: heat_rate | D33: GJ/MWh | E33: 11.999 | F33: 11.999 | G33: 11.999 | H33: 11.999 | I33: 11.999 | J33: 11.999 | K33: 11.999 | L33: 11.999 | M33: 11.999 | N33: 11.999 | O33: 11.999 | P33: 11.999 | Q33: 11.999 | R33: 11.999 | S33: 11.999 | T33: 11.999 | U33: 11.999 | V33: 11.999 | W33: 11.999 | X33: 11.999 | Y33: 11.999 | Z33: 11.999 | AA33: 11.999 | AB33: 11.999 | AC33: 11.999 | AD33: 11.999 | AE33: 11.999 | AF33: =AE33 -> 11.999 | AG33: =AF33 -> 11.999 | AH33: =AG33 -> 11.999 | AI33: =AH33 -> 11.999 | AJ33: =AI33 -> 11.999 | AK33: =AJ33 -> 11.999 | AL33: =AK33 -> 11.999 | AM33: =AL33 -> 11.999 | ... AO33: =AN33 -> 11.999
A34: default | B34: biomass_MSW | C34: heat_rate | D34: GJ/MWh | E34: 18.991 | F34: 18.991 | G34: 18.991 | H34: 18.991 | I34: 18.991 | J34: 18.991 | K34: 18.991 | L34: 18.991 | M34: 18.991 | N34: 18.991 | O34: 18.991 | P34: 18.991 | Q34: 18.991 | R34: 18.991 | S34: 18.991 | T34: 18.991 | U34: 18.991 | V34: 18.991 | W34: 18.991 | X34: 18.991 | Y34: 18.991 | Z34: 18.991 | AA34: 18.991 | AB34: 18.991 | AC34: 18.991 | AD34: 18.991 | AE34: 18.991 | AF34: =AE34 -> 18.991 | AG34: =AF34 -> 18.991 | AH34: =AG34 -> 18.991 | AI34: =AH34 -> 18.991 | AJ34: =AI34 -> 18.991 | AK34: =AJ34 -> 18.991 | AL34: =AK34 -> 18.991 | AM34: =AL34 -> 18.991 | ... AO34: =AN34 -> 18.991
A35: default | B35: ccgt_steam | C35: heat_rate | D35: GJ/MWh | E35: 0 | F35: 0 | G35: 0 | H35: 0 | I35: 0 | J35: 0 | K35: 0 | L35: 0 | M35: 0 | N35: 0 | O35: 0 | P35: 0 | Q35: 0 | R35: 0 | S35: 0 | T35: 0 | U35: 0 | V35: 0 | W35: 0 | X35: 0 | Y35: 0 | Z35: 0 | AA35: 0 | AB35: 0 | AC35: 0 | AD35: 0 | AE35: 0 | AF35: =AE35 -> 0 | AG35: =AF35 -> 0 | AH35: =AG35 -> 0 | AI35: =AH35 -> 0 | AJ35: =AI35 -> 0 | AK35: =AJ35 -> 0 | AL35: =AK35 -> 0 | AM35: =AL35 -> 0 | ... AO35: =AN35 -> 0
A36: default | B36: coal | C36: heat_rate | D36: GJ/MWh | E36: 9.776 | F36: 9.776 | G36: 9.776 | H36: 9.776 | I36: 9.776 | J36: 9.776 | K36: 9.776 | L36: 9.776 | M36: 9.776 | N36: 9.776 | O36: 9.776 | P36: 9.776 | Q36: 9.776 | R36: 9.776 | S36: 9.776 | T36: 9.776 | U36: 9.776 | V36: 9.776 | W36: 9.776 | X36: 9.776 | Y36: 9.776 | Z36: 9.776 | AA36: 9.776 | AB36: 9.776 | AC36: 9.776 | AD36: 9.776 | AE36: 9.776 | AF36: =AE36 -> 9.776 | AG36: =AF36 -> 9.776 | AH36: =AG36 -> 9.776 | AI36: =AH36 -> 9.776 | AJ36: =AI36 -> 9.776 | AK36: =AJ36 -> 9.776 | AL36: =AK36 -> 9.776 | AM36: =AL36 -> 9.776 | ... AO36: =AN36 -> 9.776
A37: default | B37: nuclear | C37: heat_rate | D37: GJ/MWh | E37: 11.25 | F37: 11.25 | G37: 11.25 | H37: 11.25 | I37: 11.25 | J37: 11.25 | K37: 11.25 | L37: 11.25 | M37: 11.25 | N37: 11.25 | O37: 11.25 | P37: 11.25 | Q37: 11.25 | R37: 11.25 | S37: 11.25 | T37: 11.25 | U37: 11.25 | V37: 11.25 | W37: 11.25 | X37: 11.25 | Y37: 11.25 | Z37: 11.25 | AA37: 11.25 | AB37: 11.25 | AC37: 11.25 | AD37: 11.25 | AE37: 11.25 | AF37: =AE37 -> 11.25 | AG37: =AF37 -> 11.25 | AH37: =AG37 -> 11.25 | AI37: =AH37 -> 11.25 | AJ37: =AI37 -> 11.25 | AK37: =AJ37 -> 11.25 | AL37: =AK37 -> 11.25 | AM37: =AL37 -> 11.25 | ... AO37: =AN37 -> 11.25
A38: default | B38: ocgt_diesel | C38: heat_rate | D38: GJ/MWh | E38: 9.453 | F38: 9.453 | G38: 9.453 | H38: 9.453 | I38: 9.453 | J38: 9.453 | K38: 9.453 | L38: 9.453 | M38: 9.453 | N38: 9.453 | O38: 9.453 | P38: 9.453 | Q38: 9.453 | R38: 9.453 | S38: 9.453 | T38: 9.453 | U38: 9.453 | V38: 9.453 | W38: 9.453 | X38: 9.453 | Y38: 9.453 | Z38: 9.453 | AA38: 9.453 | AB38: 9.453 | AC38: 9.453 | AD38: 9.453 | AE38: 9.453 | AF38: =AE38 -> 9.453 | AG38: =AF38 -> 9.453 | AH38: =AG38 -> 9.453 | AI38: =AH38 -> 9.453 | AJ38: =AI38 -> 9.453 | AK38: =AJ38 -> 9.453 | AL38: =AK38 -> 9.453 | AM38: =AL38 -> 9.453 | ... AO38: =AN38 -> 9.453
A39: default | B39: ocgt_diesel_emg | C39: heat_rate | D39: =D38 -> GJ/MWh | E39: 9.453 | F39: =F38 -> 9.453 | G39: =G38 -> 9.453 | H39: =H38 -> 9.453 | I39: =I38 -> 9.453 | J39: =J38 -> 9.453 | K39: =K38 -> 9.453 | L39: =L38 -> 9.453 | M39: =M38 -> 9.453 | ... AE39: =AE38 -> 9.453 | AF39: =AE39 -> 9.453 | AG39: =AF39 -> 9.453 | AH39: =AG39 -> 9.453 | AI39: =AH39 -> 9.453 | AJ39: =AI39 -> 9.453 | AK39: =AJ39 -> 9.453 | AL39: =AK39 -> 9.453 | AM39: =AL39 -> 9.453 | ... AO39: =AN39 -> 9.453
A40: default | B40: ocgt_gas | C40: heat_rate | D40: GJ/MWh | E40: 9.453 | F40: 9.453 | G40: 9.453 | H40: 9.453 | I40: 9.453 | J40: 9.453 | K40: 9.453 | L40: 9.453 | M40: 9.453 | N40: 9.453 | O40: 9.453 | P40: 9.453 | Q40: 9.453 | R40: 9.453 | S40: 9.453 | T40: 9.453 | U40: 9.453 | V40: 9.453 | W40: 9.453 | X40: 9.453 | Y40: 9.453 | Z40: 9.453 | AA40: 9.453 | AB40: 9.453 | AC40: 9.453 | AD40: 9.453 | AE40: 9.453 | AF40: =AE40 -> 9.453 | AG40: =AF40 -> 9.453 | AH40: =AG40 -> 9.453 | AI40: =AH40 -> 9.453 | AJ40: =AI40 -> 9.453 | AK40: =AJ40 -> 9.453 | AL40: =AK40 -> 9.453 | AM40: =AL40 -> 9.453 | ... AO40: =AN40 -> 9.453
...

Sheet max_total_installed
A1: scenario | B1: supply_region | C1: location | D1: component | E1: carrier | F1: category | G1: 2020 | H1: 2021 | I1: 2022 | J1: 2023 | K1: 2024 | L1: 2025 | M1: 2026 | N1: 2027 | O1: 2028 | P1: 2029 | Q1: 2030 | R1: 2031 | S1: 2032 | T1: 2033 | U1: 2034 | V1: 2035 | W1: 2036 | X1: 2037 | Y1: 2038 | Z1: 2039 | AA1: 2040 | AB1: 2041 | AC1: 2042 | AD1: 2043 | AE1: 2044 | AF1: 2045 | AG1: 2046 | AH1: 2047 | AI1: 2048 | AJ1: 2049 | AK1: 2050 | AL1: =AK1+1 -> 2051 | AM1: =AL1+1 -> 2052 | AN1: =AM1+1 -> 2053 | AO1: =AN1+1 -> 2054 | AP1: =AO1+1 -> 2055 | AQ1: =AP1+1 -> 2056 | AR1: =AQ1+1 -> 2057 | AS1: =AR1+1 -> 2058 | ... AU1: =AT1+1 -> 2060
A2: LEAST_CNST | B2: 1 | C2: RSA | D2: Generator | E2: solar_pv | F2: renewables | L2: unc | M2: unc | N2: unc | O2: unc | P2: unc | Q2: unc | R2: unc | S2: unc | T2: unc | U2: unc | V2: unc | W2: unc | X2: unc | Y2: unc | Z2: unc | AA2: unc | AB2: unc | AC2: unc | AD2: unc | AE2: unc | AF2: unc | AG2: unc | AH2: unc | AI2: unc | AJ2: unc | AK2: unc | AL2: =AK2 -> unc | AM2: =AL2 -> unc | AN2: =AM2 -> unc | AO2: =AN2 -> unc | AP2: =AO2 -> unc | AQ2: =AP2 -> unc | AR2: =AQ2 -> unc | AS2: =AR2 -> unc | ... AU2: =AT2 -> unc
A3: =A2 -> LEAST_CNST | B3: 1 | C3: RSA | D3: Generator | E3: solar_pv_low | F3: renewables | L3: unc | M3: unc | N3: unc | O3: unc | P3: unc | Q3: unc | R3: unc | S3: =R3 -> unc | T3: =S3 -> unc | U3: =T3 -> unc | V3: =U3 -> unc | W3: =V3 -> unc | X3: =W3 -> unc | Y3: =X3 -> unc | Z3: =Y3 -> unc | ... AU3: =AT3 -> unc
A4: =A3 -> LEAST_CNST | B4: 1 | C4: RSA | D4: Generator | E4: solar_pv_rooftop | F4: renewables | G4: 0 | H4: 0 | I4: 0 | J4: 0 | K4: 0 | L4: =min_total_installed!G2 -> 4624 | M4: =min_total_installed!H2 -> 5299 | N4: =min_total_installed!I2 -> 5974 | O4: =min_total_installed!J2 -> 6649 | P4: =min_total_installed!K2 -> 7324 | Q4: =min_total_installed!L2 -> 7999 | R4: =min_total_installed!M2 -> 8674 | S4: =min_total_installed!N2 -> 9349 | ... AU4: =min_total_installed!AP2 -> 11374
A5: =A4 -> LEAST_CNST | B5: 1 | C5: RSA | D5: Generator | E5: solar_csp | F5: renewables | L5: unc | M5: unc | N5: unc | O5: unc | P5: unc | Q5: unc | R5: unc | S5: =R5 -> unc | T5: =S5 -> unc | U5: =T5 -> unc | V5: =U5 -> unc | W5: =V5 -> unc | X5: =W5 -> unc | Y5: =X5 -> unc | Z5: =Y5 -> unc | ... AU5: =AT5 -> unc
A6: =A5 -> LEAST_CNST | B6: 1 | C6: RSA | D6: Generator | E6: wind | F6: renewables | L6: unc | M6: unc | N6: unc | O6: unc | P6: unc | Q6: 11000 | R6: unc | S6: =R6 -> unc | T6: =S6 -> unc | U6: =T6 -> unc | V6: =U6 -> unc | W6: =V6 -> unc | X6: =W6 -> unc | Y6: =X6 -> unc | Z6: =Y6 -> unc | ... AU6: =AT6 -> unc
A7: =A6 -> LEAST_CNST | B7: 1 | C7: RSA | D7: Generator | E7: wind_low | F7: renewables | L7: unc | M7: unc | N7: unc | O7: unc | P7: unc | Q7: unc | R7: unc | S7: =R7 -> unc | T7: =S7 -> unc | U7: =T7 -> unc | V7: =U7 -> unc | W7: =V7 -> unc | X7: =W7 -> unc | Y7: =X7 -> unc | Z7: =Y7 -> unc | ... AU7: =AT7 -> unc
A8: =A7 -> LEAST_CNST | B8: 1 | C8: RSA | D8: Generator | E8: ccgt_steam | F8: conventional | L8: unc | M8: unc | N8: unc | O8: unc | P8: unc | Q8: unc | R8: unc | S8: =R8 -> unc | T8: =S8 -> unc | U8: =T8 -> unc | V8: =U8 -> unc | W8: =V8 -> unc | X8: =W8 -> unc | Y8: =X8 -> unc | Z8: =Y8 -> unc | ... AU8: =AT8 -> unc
A9: =A8 -> LEAST_CNST | B9: 1 | C9: RSA | D9: Generator | E9: ocgt_gas | F9: conventional | L9: unc | M9: unc | N9: unc | O9: unc | P9: unc | Q9: unc | R9: unc | S9: =R9 -> unc | T9: =S9 -> unc | U9: =T9 -> unc | V9: =U9 -> unc | W9: =V9 -> unc | X9: =W9 -> unc | Y9: =X9 -> unc | Z9: =Y9 -> unc | ... AU9: =AT9 -> unc
A10: =A9 -> LEAST_CNST | B10: 1 | C10: RSA | D10: Generator | E10: ocgt_gas_h2_40 | F10: conventional | L10: unc | M10: unc | N10: unc | O10: unc | P10: unc | Q10: unc | R10: unc | S10: =R10 -> unc | T10: =S10 -> unc | U10: =T10 -> unc | V10: =U10 -> unc | W10: =V10 -> unc | X10: =W10 -> unc | Y10: =X10 -> unc | Z10: =Y10 -> unc | ... AU10: =AT10 -> unc
A11: =A10 -> LEAST_CNST | B11: 1 | C11: RSA | D11: Generator | E11: ocgt_gas_h2_45 | F11: conventional | L11: unc | M11: unc | N11: unc | O11: unc | P11: unc | Q11: unc | R11: unc | S11: =R11 -> unc | T11: =S11 -> unc | U11: =T11 -> unc | V11: =U11 -> unc | W11: =V11 -> unc | X11: =W11 -> unc | Y11: =X11 -> unc | Z11: =Y11 -> unc | ... AU11: =AT11 -> unc
A12: =A11 -> LEAST_CNST | B12: 1 | C12: RSA | D12: Generator | E12: ocgt_gas_h2_50 | F12: conventional | L12: unc | M12: unc | N12: unc | O12: unc | P12: unc | Q12: unc | R12: unc | S12: =R12 -> unc | T12: =S12 -> unc | U12: =T12 -> unc | V12: =U12 -> unc | W12: =V12 -> unc | X12: =W12 -> unc | Y12: =X12 -> unc | Z12: =Y12 -> unc | ... AU12: =AT12 -> unc
A13: =A12 -> LEAST_CNST | B13: 1 | C13: RSA | D13: Generator | E13: ocgt_gas_h2_55 | F13: conventional | L13: unc | M13: unc | N13: unc | O13: unc | P13: unc | Q13: unc | R13: unc | S13: =R13 -> unc | T13: =S13 -> unc | U13: =T13 -> unc | V13: =U13 -> unc | W13: =V13 -> unc | X13: =W13 -> unc | Y13: =X13 -> unc | Z13: =Y13 -> unc | ... AU13: =AT13 -> unc
A14: =A13 -> LEAST_CNST | B14: 1 | C14: RSA | D14: Generator | E14: ocgt_gas_h2_60 | F14: conventional | L14: unc | M14: unc | N14: unc | O14: unc | P14: unc | Q14: unc | R14: unc | S14: =R14 -> unc | T14: =S14 -> unc | U14: =T14 -> unc | V14: =U14 -> unc | W14: =V14 -> unc | X14: =W14 -> unc | Y14: =X14 -> unc | Z14: =Y14 -> unc | ... AU14: =AT14 -> unc
A15: =A12 -> LEAST_CNST | B15: 1 | C15: RSA | D15: Generator | E15: ocgt_diesel | F15: conventional | L15: unc | M15: unc | N15: unc | O15: unc | P15: unc | Q15: unc | R15: unc | S15: =R15 -> unc | T15: =S15 -> unc | U15: =T15 -> unc | V15: =U15 -> unc | W15: =V15 -> unc | X15: =W15 -> unc | Y15: =X15 -> unc | Z15: =Y15 -> unc | ... AU15: =AT15 -> unc
A16: =A13 -> LEAST_CNST | B16: 1 | C16: RSA | D16: Generator | E16: ocgt_blend | F16: conventional | L16: unc | M16: unc | N16: unc | O16: unc | P16: unc | Q16: unc | R16: unc | S16: =R16 -> unc | T16: =S16 -> unc | U16: =T16 -> unc | V16: =U16 -> unc | W16: =V16 -> unc | X16: =W16 -> unc | Y16: =X16 -> unc | Z16: =Y16 -> unc | ... AU16: =AT16 -> unc
A17: =A15 -> LEAST_CNST | B17: 1 | C17: RSA | D17: Generator | E17: coal | F17: conventional | L17: 0 | M17: 0 | N17: 0 | O17: 0 | P17: 0 | Q17: 0 | R17: 0 | S17: 0 | T17: 0 | U17: 0 | V17: unc | W17: unc | X17: unc | Y17: unc | Z17: unc | AA17: unc | AB17: unc | AC17: unc | AD17: unc | AE17: unc | AF17: unc | AG17: unc | AH17: unc | AI17: unc | AJ17: unc | AK17: unc | AL17: =AK17 -> unc | AM17: =AL17 -> unc | AN17: =AM17 -> unc | AO17: =AN17 -> unc | AP17: =AO17 -> unc | AQ17: =AP17 -> unc | AR17: =AQ17 -> unc | AS17: =AR17 -> unc | ... AU17: =AT17 -> unc
A18: =A17 -> LEAST_CNST | B18: 1 | C18: RSA | D18: Generator | E18: nuclear | F18: conventional | L18: 0 | M18: 0 | N18: 0 | O18: 0 | P18: 0 | Q18: 0 | R18: 0 | S18: 0 | T18: 0 | U18: 0 | V18: unc | W18: unc | X18: unc | Y18: unc | Z18: unc | AA18: unc | AB18: unc | AC18: unc | AD18: unc | AE18: unc | AF18: unc | AG18: unc | AH18: unc | AI18: unc | AJ18: unc | AK18: unc | AL18: =AK18 -> unc | AM18: =AL18 -> unc | AN18: =AM18 -> unc | AO18: =AN18 -> unc | AP18: =AO18 -> unc | AQ18: =AP18 -> unc | AR18: =AQ18 -> unc | AS18: =AR18 -> unc | ... AU18: =AT18 -> unc
A19: =A18 -> LEAST_CNST | B19: 1 | C19: RSA | D19: StorageUnit | E19: phs | F19: storage | L19: 0 | M19: 0 | N19: 0 | O19: 0 | P19: 0 | Q19: 0 | R19: 0 | S19: 0 | T19: 0 | U19: 0 | V19: 1500 | W19: =V19 -> 1500 | X19: =W19 -> 1500 | Y19: =X19 -> 1500 | Z19: =Y19 -> 1500 | AA19: =Z19 -> 1500 | AB19: =AA19 -> 1500 | AC19: =AB19 -> 1500 | AD19: =AC19 -> 1500 | ... AU19: =AT19 -> 1500
A20: =A19 -> LEAST_CNST | B20: 1 | C20: RSA | D20: StorageUnit | E20: battery_1h | F20: storage | L20: unc | M20: unc | N20: unc | O20: unc | P20: unc | Q20: unc | R20: unc | S20: unc | T20: unc | U20: unc | V20: unc | W20: unc | X20: unc | Y20: unc | Z20: unc | AA20: unc | AB20: unc | AC20: unc | AD20: unc | AE20: unc | AF20: unc | AG20: unc | AH20: unc | AI20: unc | AJ20: unc | AK20: unc | AL20: =AK20 -> unc | AM20: =AL20 -> unc | AN20: =AM20 -> unc | AO20: =AN20 -> unc | AP20: =AO20 -> unc | AQ20: =AP20 -> unc | AR20: =AQ20 -> unc | AS20: =AR20 -> unc | ... AU20: =AT20 -> unc
A21: =A20 -> LEAST_CNST | B21: 1 | C21: RSA | D21: StorageUnit | E21: battery_4h | F21: storage | L21: unc | M21: unc | N21: unc | O21: unc | P21: unc | Q21: unc | R21: unc | S21: unc | T21: unc | U21: unc | V21: unc | W21: unc | X21: unc | Y21: unc | Z21: unc | AA21: unc | AB21: unc | AC21: unc | AD21: unc | AE21: unc | AF21: unc | AG21: unc | AH21: unc | AI21: unc | AJ21: unc | AK21: unc | AL21: =AK21 -> unc | AM21: =AL21 -> unc | AN21: =AM21 -> unc | AO21: =AN21 -> unc | AP21: =AO21 -> unc | AQ21: =AP21 -> unc | AR21: =AQ21 -> unc | AS21: =AR21 -> unc | ... AU21: =AT21 -> unc
A22: =A21 -> LEAST_CNST | B22: 1 | C22: RSA | D22: StorageUnit | E22: battery_8h | F22: storage | L22: unc | M22: unc | N22: unc | O22: unc | P22: unc | Q22: unc | R22: unc | S22: unc | T22: unc | U22: unc | V22: unc | W22: unc | X22: unc | Y22: unc | Z22: unc | AA22: unc | AB22: unc | AC22: unc | AD22: unc | AE22: unc | AF22: unc | AG22: unc | AH22: unc | AI22: unc | AJ22: unc | AK22: unc | AL22: =AK22 -> unc | AM22: =AL22 -> unc | AN22: =AM22 -> unc | AO22: =AN22 -> unc | AP22: =AO22 -> unc | AQ22: =AP22 -> unc | AR22: =AQ22 -> unc | AS22: =AR22 -> unc | ... AU22: =AT22 -> unc
A23: MOD_CNST | B23: 1 | C23: RSA | D23: Generator | E23: solar_pv | F23: renewables | L23: unc | M23: unc | N23: unc | O23: unc | P23: unc | Q23: unc | R23: unc | S23: =R23 -> unc | T23: =S23 -> unc | U23: =T23 -> unc | V23: =U23 -> unc | W23: =V23 -> unc | X23: =W23 -> unc | Y23: =X23 -> unc | Z23: =Y23 -> unc | ... AU23: =AT23 -> unc
A24: =A23 -> MOD_CNST | B24: 1 | C24: RSA | D24: Generator | E24: solar_pv_low | F24: renewables | L24: unc | M24: unc | N24: unc | O24: unc | P24: unc | Q24: unc | R24: unc | S24: =R24 -> unc | T24: =S24 -> unc | U24: =T24 -> unc | V24: =U24 -> unc | W24: =V24 -> unc | X24: =W24 -> unc | Y24: =X24 -> unc | Z24: =Y24 -> unc | ... AU24: =AT24 -> unc
A25: =A24 -> MOD_CNST | B25: 1 | C25: RSA | D25: Generator | E25: solar_pv_rooftop | F25: renewables | L25: =min_total_installed!G2 -> 4624 | M25: =min_total_installed!H2 -> 5299 | N25: =min_total_installed!I2 -> 5974 | O25: =min_total_installed!J2 -> 6649 | P25: =min_total_installed!K2 -> 7324 | Q25: =min_total_installed!L2 -> 7999 | R25: =min_total_installed!M2 -> 8674 | S25: =min_total_installed!N2 -> 9349 | ... AU25: =min_total_installed!AP2 -> 11374
A26: =A25 -> MOD_CNST | B26: 1 | C26: RSA | D26: Generator | E26: solar_csp | F26: renewables | L26: unc | M26: unc | N26: unc | O26: unc | P26: unc | Q26: unc | R26: unc | S26: =R26 -> unc | T26: =S26 -> unc | U26: =T26 -> unc | V26: =U26 -> unc | W26: =V26 -> unc | X26: =W26 -> unc | Y26: =X26 -> unc | Z26: =Y26 -> unc | ... AU26: =AT26 -> unc
A27: =A26 -> MOD_CNST | B27: 1 | C27: RSA | D27: Generator | E27: wind | F27: renewables | L27: unc | M27: unc | N27: unc | O27: unc | P27: unc | Q27: 9000 | R27: unc | S27: =R27 -> unc | T27: =S27 -> unc | U27: =T27 -> unc | V27: =U27 -> unc | W27: =V27 -> unc | X27: =W27 -> unc | Y27: =X27 -> unc | Z27: =Y27 -> unc | ... AU27: =AT27 -> unc
A28: =A27 -> MOD_CNST | B28: 1 | C28: RSA | D28: Generator | E28: wind_low | F28: renewables | L28: unc | M28: unc | N28: unc | O28: unc | P28: unc | Q28: unc | R28: unc | S28: =R28 -> unc | T28: =S28 -> unc | U28: =T28 -> unc | V28: =U28 -> unc | W28: =V28 -> unc | X28: =W28 -> unc | Y28: =X28 -> unc | Z28: =Y28 -> unc | ... AU28: =AT28 -> unc
A29: =A28 -> MOD_CNST | B29: 1 | C29: RSA | D29: Generator | E29: ccgt_steam | F29: conventional | L29: unc | M29: unc | N29: unc | O29: unc | P29: unc | Q29: unc | R29: unc | S29: =R29 -> unc | T29: =S29 -> unc | U29: =T29 -> unc | V29: =U29 -> unc | W29: =V29 -> unc | X29: =W29 -> unc | Y29: =X29 -> unc | Z29: =Y29 -> unc | ... AU29: =AT29 -> unc
A30: =A29 -> MOD_CNST | B30: 1 | C30: RSA | D30: Generator | E30: ocgt_gas | F30: conventional | L30: unc | M30: unc | N30: unc | O30: unc | P30: unc | Q30: unc | R30: unc | S30: =R30 -> unc | T30: =S30 -> unc | U30: =T30 -> unc | V30: =U30 -> unc | W30: =V30 -> unc | X30: =W30 -> unc | Y30: =X30 -> unc | Z30: =Y30 -> unc | ... AU30: =AT30 -> unc
A31: =A30 -> MOD_CNST | B31: 1 | C31: RSA | D31: Generator | E31: ocgt_gas_h2_40 | F31: conventional | L31: unc | M31: unc | N31: unc | O31: unc | P31: unc | Q31: unc | R31: unc | S31: =R31 -> unc | T31: =S31 -> unc | U31: =T31 -> unc | V31: =U31 -> unc | W31: =V31 -> unc | X31: =W31 -> unc | Y31: =X31 -> unc | Z31: =Y31 -> unc | ... AU31: =AT31 -> unc
A32: =A31 -> MOD_CNST | B32: 1 | C32: RSA | D32: Generator | E32: ocgt_gas_h2_45 | F32: conventional | L32: unc | M32: unc | N32: unc | O32: unc | P32: unc | Q32: unc | R32: unc | S32: =R32 -> unc | T32: =S32 -> unc | U32: =T32 -> unc | V32: =U32 -> unc | W32: =V32 -> unc | X32: =W32 -> unc | Y32: =X32 -> unc | Z32: =Y32 -> unc | ... AU32: =AT32 -> unc
A33: =A32 -> MOD_CNST | B33: 1 | C33: RSA | D33: Generator | E33: ocgt_gas_h2_50 | F33: conventional | L33: unc | M33: unc | N33: unc | O33: unc | P33: unc | Q33: unc | R33: unc | S33: =R33 -> unc | T33: =S33 -> unc | U33: =T33 -> unc | V33: =U33 -> unc | W33: =V33 -> unc | X33: =W33 -> unc | Y33: =X33 -> unc | Z33: =Y33 -> unc | ... AU33: =AT33 -> unc
A34: =A33 -> MOD_CNST | B34: 1 | C34: RSA | D34: Generator | E34: ocgt_gas_h2_55 | F34: conventional | L34: unc | M34: unc | N34: unc | O34: unc | P34: unc | Q34: unc | R34: unc | S34: =R34 -> unc | T34: =S34 -> unc | U34: =T34 -> unc | V34: =U34 -> unc | W34: =V34 -> unc | X34: =W34 -> unc | Y34: =X34 -> unc | Z34: =Y34 -> unc | ... AU34: =AT34 -> unc
A35: =A34 -> MOD_CNST | B35: 1 | C35: RSA | D35: Generator | E35: ocgt_gas_h2_60 | F35: conventional | L35: unc | M35: unc | N35: unc | O35: unc | P35: unc | Q35: unc | R35: unc | S35: =R35 -> unc | T35: =S35 -> unc | U35: =T35 -> unc | V35: =U35 -> unc | W35: =V35 -> unc | X35: =W35 -> unc | Y35: =X35 -> unc | Z35: =Y35 -> unc | ... AU35: =AT35 -> unc
A36: =A33 -> MOD_CNST | B36: 1 | C36: RSA | D36: Generator | E36: ocgt_diesel | F36: conventional | L36: unc | M36: unc | N36: unc | O36: unc | P36: unc | Q36: unc | R36: unc | S36: =R36 -> unc | T36: =S36 -> unc | U36: =T36 -> unc | V36: =U36 -> unc | W36: =V36 -> unc | X36: =W36 -> unc | Y36: =X36 -> unc | Z36: =Y36 -> unc | ... AU36: =AT36 -> unc
A37: =A34 -> MOD_CNST | B37: 1 | C37: RSA | D37: Generator | E37: ocgt_blend | F37: conventional | L37: 0 | M37: 0 | N37: 0 | O37: 0 | P37: 0 | Q37: 0 | R37: 0 | S37: 0 | T37: 0 | U37: 0 | V37: 0 | W37: =V37 -> 0 | X37: =W37 -> 0 | Y37: =X37 -> 0 | Z37: =Y37 -> 0 | AA37: =Z37 -> 0 | AB37: =AA37 -> 0 | AC37: =AB37 -> 0 | AD37: =AC37 -> 0 | ... AU37: =AT37 -> 0
A38: =A36 -> MOD_CNST | B38: 1 | C38: RSA | D38: Generator | E38: coal | F38: conventional | L38: 0 | M38: 0 | N38: 0 | O38: 0 | P38: 0 | Q38: 0 | R38: 0 | S38: 0 | T38: 0 | U38: 0 | V38: unc | W38: unc | X38: unc | Y38: unc | Z38: unc | AA38: unc | AB38: =AA38 -> unc | AC38: =AB38 -> unc | AD38: =AC38 -> unc | AE38: =AD38 -> unc | AF38: =AE38 -> unc | AG38: =AF38 -> unc | AH38: =AG38 -> unc | AI38: =AH38 -> unc | ... AU38: =AT38 -> unc
A39: =A38 -> MOD_CNST | B39: 1 | C39: RSA | D39: Generator | E39: nuclear | F39: conventional | L39: 0 | M39: 0 | N39: 0 | O39: 0 | P39: 0 | Q39: 0 | R39: 0 | S39: 0 | T39: 0 | U39: 0 | V39: unc | W39: unc | X39: unc | Y39: unc | Z39: unc | AA39: unc | AB39: =AA39 -> unc | AC39: =AB39 -> unc | AD39: =AC39 -> unc | AE39: =AD39 -> unc | AF39: =AE39 -> unc | AG39: =AF39 -> unc | AH39: =AG39 -> unc | AI39: =AH39 -> unc | ... AU39: =AT39 -> unc
A40: =A39 -> MOD_CNST | B40: 1 | C40: RSA | D40: StorageUnit | E40: phs | F40: storage | L40: 0 | M40: 0 | N40: 0 | O40: 0 | P40: 0 | Q40: 0 | R40: 0 | S40: 0 | T40: 0 | U40: 0 | V40: 1500 | W40: =V40 -> 1500 | X40: =W40 -> 1500 | Y40: =X40 -> 1500 | Z40: =Y40 -> 1500 | AA40: =Z40 -> 1500 | AB40: =AA40 -> 1500 | AC40: =AB40 -> 1500 | AD40: =AC40 -> 1500 | ... AU40: =AT40 -> 1500
...

Sheet min_total_installed
A1: scenario | B1: supply_region | C1: location | D1: component | E1: carrier | F1: category | G1: 2025 | H1: =G1+1 -> 2026 | I1: =H1+1 -> 2027 | J1: =I1+1 -> 2028 | K1: =J1+1 -> 2029 | L1: =K1+1 -> 2030 | M1: =L1+1 -> 2031 | N1: =M1+1 -> 2032 | O1: =N1+1 -> 2033 | ... AP1: =AO1+1 -> 2060
A2: UNC | B2: 1 | C2: RSA | D2: Generator | E2: solar_pv_rooftop | F2: renewables | G2: 4624 | H2: =G2+0.75*900 -> 5299 | I2: =H2+0.75*900 -> 5974 | J2: =I2+0.75*900 -> 6649 | K2: =J2+0.75*900 -> 7324 | L2: =K2+0.75*900 -> 7999 | M2: =L2+0.75*900 -> 8674 | N2: =M2+0.75*900 -> 9349 | O2: =N2+0.75*900 -> 10024 | ... Q2: =P2+0.75*900 -> 11374 | R2: =Q2 -> 11374 | S2: =R2 -> 11374 | T2: =S2 -> 11374 | U2: =T2 -> 11374 | V2: =U2 -> 11374 | W2: =V2 -> 11374 | X2: =W2 -> 11374 | Y2: =X2 -> 11374 | ... AP2: =AO2 -> 11374
A3: UNC | B3: 1 | C3: RSA | D3: Generator | E3: solar_pv_low | F3: renewables | G3: 1541 | H3: =G3+0.25*900 -> 1766 | I3: =H3+0.25*900 -> 1991 | J3: =I3+0.25*900 -> 2216 | K3: =J3+0.25*900 -> 2441 | L3: =K3+0.25*900 -> 2666 | M3: =L3+0.25*900 -> 2891 | N3: =M3+0.25*900 -> 3116 | O3: =N3+0.25*900 -> 3341 | ... Q3: =P3+0.25*900 -> 3791 | R3: =Q3 -> 3791 | S3: =R3 -> 3791 | T3: =S3 -> 3791 | U3: =T3 -> 3791 | V3: =U3 -> 3791 | W3: =V3 -> 3791 | X3: =W3 -> 3791 | Y3: =X3 -> 3791 | ... AP3: =AO3 -> 3791
A4: ignore | B4: 1 | C4: RSA | D4: Generator | E4: solar_pv_low_tot | F4: renewables | G4: =G2+G3 -> 6165 | H4: =H2+H3 -> 7065 | I4: =I2+I3 -> 7965 | J4: =J2+J3 -> 8865 | K4: =K2+K3 -> 9765 | L4: =L2+L3 -> 10665 | M4: =M2+M3 -> 11565 | N4: =N2+N3 -> 12465 | ... Q4: =Q2+Q3 -> 15165 | R4: =Q4 -> 15165 | S4: =R4 -> 15165 | T4: =S4 -> 15165 | U4: =T4 -> 15165 | V4: =U4 -> 15165 | W4: =V4 -> 15165 | X4: =W4 -> 15165 | Y4: =X4 -> 15165 | ... AP4: =AO4 -> 15165
A5: MTSAO_BQ | B5: 1 | C5: RSA | D5: Generator | E5: solar_pv_low | F5: renewables | G5: =G3 -> 1541 | H5: =H3 -> 1766 | I5: =I3 -> 1991 | J5: =J3 -> 2216 | K5: =K3 -> 2441 | L5: 4768 | M5: 0 | N5: 0 | O5: 0 | P5: 0 | Q5: 0 | R5: 0 | S5: 0 | T5: 0 | U5: 0 | V5: 0 | W5: 0 | X5: 0 | Y5: 0 | Z5: 0 | AA5: 0 | AB5: 0 | AC5: 0 | AD5: 0 | AE5: 0 | AF5: 0 | AG5: =AF5 -> 0 | AH5: =AG5 -> 0 | AI5: =AH5 -> 0 | AJ5: =AI5 -> 0 | AK5: =AJ5 -> 0 | AL5: =AK5 -> 0 | AM5: =AL5 -> 0 | AN5: =AM5 -> 0 | ... AP5: =AO5 -> 0
A6: =A5 -> MTSAO_BQ | B6: 1 | C6: RSA | D6: Generator | E6: solar_pv_rooftop | F6: renewables | G6: =G2 -> 4624 | H6: =H2 -> 5299 | I6: =I2 -> 5974 | J6: =J2 -> 6649 | K6: =K2 -> 7324 | L6: =L2 -> 7999 | M6: =M2 -> 8674 | N6: =N2 -> 9349 | ... AP6: =AP2 -> 11374
A7: =A6 -> MTSAO_BQ | B7: 1 | C7: RSA | D7: Generator | E7: wind | F7: renewables | G7: 5 | H7: 0 | I7: 0 | J7: 0 | K7: 0 | L7: 3895 | M7: 0 | N7: 0 | O7: 0 | P7: 0 | Q7: 0 | R7: 0 | S7: 0 | T7: 0 | U7: 0 | V7: 0 | W7: 0 | X7: 0 | Y7: 0 | Z7: 0 | AA7: 0 | AB7: 0 | AC7: 0 | AD7: 0 | AE7: 0 | AF7: 0 | AG7: =AF7 -> 0 | AH7: =AG7 -> 0 | AI7: =AH7 -> 0 | AJ7: =AI7 -> 0 | AK7: =AJ7 -> 0 | AL7: =AK7 -> 0 | AM7: =AL7 -> 0 | AN7: =AM7 -> 0 | ... AP7: =AO7 -> 0
A8: =A7 -> MTSAO_BQ | B8: 1 | C8: RSA | D8: Generator | E8: wind_low | F8: renewables | G8: 5 | H8: 0 | I8: 0 | J8: 0 | K8: 0 | L8: 0 | M8: 0 | N8: 0 | O8: 0 | P8: 0 | Q8: 0 | R8: 0 | S8: 0 | T8: 0 | U8: 0 | V8: 0 | W8: 0 | X8: 0 | Y8: 0 | Z8: 0 | AA8: 0 | AB8: 0 | AC8: 0 | AD8: 0 | AE8: 0 | AF8: 0 | AG8: =AF8 -> 0 | AH8: =AG8 -> 0 | AI8: =AH8 -> 0 | AJ8: =AI8 -> 0 | AK8: =AJ8 -> 0 | AL8: =AK8 -> 0 | AM8: =AL8 -> 0 | AN8: =AM8 -> 0 | ... AP8: =AO8 -> 0
A9: =A8 -> MTSAO_BQ | B9: 1 | C9: RSA | D9: Generator | E9: battery_4h | F9: renewables | G9: 0 | H9: 0 | I9: 0 | J9: 0 | K9: 0 | L9: 2615 | M9: 0 | N9: 0 | O9: 0 | P9: 0 | Q9: 0 | R9: 0 | S9: 0 | T9: 0 | U9: 0 | V9: 0 | W9: 0 | X9: 0 | Y9: 0 | Z9: 0 | AA9: 0 | AB9: 0 | AC9: 0 | AD9: 0 | AE9: 0 | AF9: 0 | AG9: =AF9 -> 0 | AH9: =AG9 -> 0 | AI9: =AH9 -> 0 | AJ9: =AI9 -> 0 | AK9: =AJ9 -> 0 | AL9: =AK9 -> 0 | AM9: =AL9 -> 0 | AN9: =AM9 -> 0 | ... AP9: =AO9 -> 0
A10: IRP24_BQ_IGCAR | B10: 1 | C10: RSA | D10: Generator | E10: solar_pv_low | F10: renewables | G10: =G3 -> 1541 | H10: =H3 -> 1766 | I10: =I3 -> 1991 | J10: =J3 -> 2216 | K10: =K3 -> 2441 | L10: 6988 | M10: 0 | N10: 0 | O10: 0 | P10: 0 | Q10: 0 | R10: 0 | S10: 0 | T10: 0 | U10: 0 | V10: 0 | W10: 0 | X10: 0 | Y10: 0 | Z10: 0 | AA10: 0 | AB10: 0 | AC10: 0 | AD10: 0 | AE10: 0 | AF10: 0 | AG10: =AF10 -> 0 | AH10: =AG10 -> 0 | AI10: =AH10 -> 0 | AJ10: =AI10 -> 0 | AK10: =AJ10 -> 0 | AL10: =AK10 -> 0 | AM10: =AL10 -> 0 | AN10: =AM10 -> 0 | ... AP10: =AO10 -> 0
A11: =A10 -> IRP24_BQ_IGCAR | B11: 1 | C11: RSA | D11: Generator | E11: solar_pv_rooftop | F11: renewables | G11: =G2 -> 4624 | H11: =H2 -> 5299 | I11: =I2 -> 5974 | J11: =J2 -> 6649 | K11: =K2 -> 7324 | L11: =L2 -> 7999 | M11: =M2 -> 8674 | N11: =N2 -> 9349 | ... AP11: =AP2 -> 11374
A12: =A11 -> IRP24_BQ_IGCAR | B12: 1 | C12: RSA | D12: Generator | E12: wind | F12: renewables | G12: 5 | H12: 0 | I12: 0 | J12: 0 | K12: 0 | L12: 5888 | M12: 0 | N12: 0 | O12: 0 | P12: 0 | Q12: 0 | R12: 0 | S12: 0 | T12: 0 | U12: 0 | V12: 0 | W12: 0 | X12: 0 | Y12: 0 | Z12: 0 | AA12: 0 | AB12: 0 | AC12: 0 | AD12: 0 | AE12: 0 | AF12: 0 | AG12: =AF12 -> 0 | AH12: =AG12 -> 0 | AI12: =AH12 -> 0 | AJ12: =AI12 -> 0 | AK12: =AJ12 -> 0 | AL12: =AK12 -> 0 | AM12: =AL12 -> 0 | AN12: =AM12 -> 0 | ... AP12: =AO12 -> 0
A13: =A12 -> IRP24_BQ_IGCAR | B13: 1 | C13: RSA | D13: Generator | E13: wind_low | F13: renewables | G13: 5 | H13: 0 | I13: 0 | J13: 0 | K13: 0 | L13: 500 | M13: 0 | N13: 0 | O13: 0 | P13: 0 | Q13: 0 | R13: 0 | S13: 0 | T13: 0 | U13: 0 | V13: 0 | W13: 0 | X13: 0 | Y13: 0 | Z13: 0 | AA13: 0 | AB13: 0 | AC13: 0 | AD13: 0 | AE13: 0 | AF13: 0 | AG13: =AF13 -> 0 | AH13: =AG13 -> 0 | AI13: =AH13 -> 0 | AJ13: =AI13 -> 0 | AK13: =AJ13 -> 0 | AL13: =AK13 -> 0 | AM13: =AL13 -> 0 | AN13: =AM13 -> 0 | ... AP13: =AO13 -> 0
A14: =A13 -> IRP24_BQ_IGCAR | B14: 1 | C14: RSA | D14: Generator | E14: battery_4h | F14: renewables | G14: 0 | H14: 0 | I14: 0 | J14: 0 | K14: 0 | L14: 2615 | M14: 0 | N14: 0 | O14: 0 | P14: 0 | Q14: 0 | R14: 0 | S14: 0 | T14: 0 | U14: 0 | V14: 0 | W14: 0 | X14: 0 | Y14: 0 | Z14: 0 | AA14: 0 | AB14: 0 | AC14: 0 | AD14: 0 | AE14: 0 | AF14: 0 | AG14: =AF14 -> 0 | AH14: =AG14 -> 0 | AI14: =AH14 -> 0 | AJ14: =AI14 -> 0 | AK14: =AJ14 -> 0 | AL14: =AK14 -> 0 | AM14: =AL14 -> 0 | AN14: =AM14 -> 0 | ... AP14: =AO14 -> 0

Sheet max_annual_installed
A1: scenario | B1: supply_region | C1: location | D1: component | E1: carrier | F1: category | G1: 2020 | H1: 2021 | I1: 2022 | J1: 2023 | K1: 2024 | L1: 2025 | M1: 2026 | N1: 2027 | O1: 2028 | P1: 2029 | Q1: 2030 | R1: 2031 | S1: =R1+1 -> 2032 | T1: =S1+1 -> 2033 | U1: =T1+1 -> 2034 | V1: 2035 | W1: =V1+1 -> 2036 | X1: =W1+1 -> 2037 | Y1: =X1+1 -> 2038 | Z1: =Y1+1 -> 2039 | AA1: 2040 | AB1: =AA1+1 -> 2041 | AC1: =AB1+1 -> 2042 | AD1: =AC1+1 -> 2043 | AE1: =AD1+1 -> 2044 | AF1: 2045 | AG1: =AF1+1 -> 2046 | AH1: =AG1+1 -> 2047 | AI1: =AH1+1 -> 2048 | AJ1: =AI1+1 -> 2049 | AK1: 2050 | AL1: =AK1+1 -> 2051 | AM1: =AL1+1 -> 2052 | AN1: =AM1+1 -> 2053 | AO1: =AN1+1 -> 2054 | AP1: =AO1+1 -> 2055 | AQ1: =AP1+1 -> 2056 | AR1: =AQ1+1 -> 2057 | AS1: =AR1+1 -> 2058 | ... AU1: =AT1+1 -> 2060
A2: UNC | B2: 1 | C2: RSA | D2: Generator | E2: solar_pv | F2: renewables | G2: unc | L2: unc | M2: unc | N2: unc | O2: unc | P2: unc | Q2: unc | R2: unc | S2: unc | T2: unc | U2: unc | V2: unc | W2: unc | X2: unc | Y2: unc | Z2: unc | AA2: unc | AB2: unc | AC2: unc | AD2: unc | AE2: unc | AF2: unc | AG2: unc | AH2: unc | AI2: unc | AJ2: unc | AK2: =AF2 -> unc | AL2: =AK2 -> unc | AM2: =AL2 -> unc | AN2: =AM2 -> unc | AO2: =AN2 -> unc | AP2: =AO2 -> unc | AQ2: =AP2 -> unc | AR2: =AQ2 -> unc | AS2: =AR2 -> unc | ... AU2: =AT2 -> unc
A3: LEAST_CNST | B3: 1 | C3: RSA | D3: Generator | E3: solar_pv | F3: renewables | L3: 0 | M3: 0 | N3: 0 | O3: 0 | P3: 0 | Q3: 10000 | R3: 10000 | S3: 10000 | T3: 10000 | U3: 10000 | V3: 10000 | W3: 10000 | X3: 10000 | Y3: 10000 | Z3: 10000 | AA3: 10000 | AB3: 10000 | AC3: 10000 | AD3: 10000 | AE3: 10000 | AF3: 10000 | AG3: 10000 | AH3: 10000 | AI3: 10000 | AJ3: 10000 | AK3: 10000 | AL3: =AK3 -> 10000 | AM3: =AL3 -> 10000 | AN3: =AM3 -> 10000 | AO3: =AN3 -> 10000 | AP3: =AO3 -> 10000 | AQ3: =AP3 -> 10000 | AR3: =AQ3 -> 10000 | AS3: =AR3 -> 10000 | ... AU3: =AT3 -> 10000
A4: =A3 -> LEAST_CNST | B4: 1 | C4: RSA | D4: Generator | E4: solar_pv_low | F4: renewables | L4: 2000 | M4: 10000 | N4: 10000 | O4: 10000 | P4: 10000 | Q4: 10000 | R4: 10000 | S4: 10000 | T4: 10000 | U4: 10000 | V4: 10000 | W4: 10000 | X4: 10000 | Y4: 10000 | Z4: 10000 | AA4: 10000 | AB4: 10000 | AC4: 10000 | AD4: 10000 | AE4: 10000 | AF4: 10000 | AG4: 10000 | AH4: 10000 | AI4: 10000 | AJ4: 10000 | AK4: 10000 | AL4: =AK4 -> 10000 | AM4: =AL4 -> 10000 | AN4: =AM4 -> 10000 | AO4: =AN4 -> 10000 | AP4: =AO4 -> 10000 | AQ4: =AP4 -> 10000 | AR4: =AQ4 -> 10000 | AS4: =AR4 -> 10000 | ... AU4: =AT4 -> 10000
A5: =A4 -> LEAST_CNST | B5: 1 | C5: RSA | D5: Generator | E5: solar_csp | F5: renewables | L5: 0 | M5: 0 | N5: 0 | O5: 0 | P5: 0 | Q5: 1000 | R5: =Q5 -> 1000 | S5: =R5 -> 1000 | T5: =S5 -> 1000 | U5: =T5 -> 1000 | V5: =U5 -> 1000 | W5: =V5 -> 1000 | X5: =W5 -> 1000 | Y5: =X5 -> 1000 | ... AU5: =AT5 -> 1000
A6: =A5 -> LEAST_CNST | B6: 1 | C6: RSA | D6: Generator | E6: wind | F6: renewables | L6: 5 | M6: 1000 | N6: =M6+100 -> 1100 | O6: =N6+100 -> 1200 | P6: =O6+100 -> 1300 | Q6: =P6+100 -> 1400 | R6: =Q6+100 -> 1500 | S6: =R6+100 -> 1600 | T6: =S6+100 -> 1700 | U6: =T6+100 -> 1800 | ... AU6: =AT6+100 -> 4400
A7: =A6 -> LEAST_CNST | B7: 1 | C7: RSA | D7: Generator | E7: wind_low | F7: renewables | L7: 5 | M7: 0 | N7: 0 | O7: 0 | P7: 0 | Q7: 1500 | R7: =Q7 -> 1500 | S7: =R7 -> 1500 | T7: =S7 -> 1500 | U7: =T7 -> 1500 | V7: =U7 -> 1500 | W7: =V7 -> 1500 | X7: =W7 -> 1500 | Y7: =X7 -> 1500 | ... AU7: =AT7 -> 1500
A8: =A7 -> LEAST_CNST | B8: 1 | C8: RSA | D8: Generator | E8: ccgt_steam | F8: conventional | L8: 0 | M8: 0 | N8: 0 | O8: 0 | P8: 0 | Q8: unc | R8: unc | S8: =R8 -> unc | T8: =S8 -> unc | U8: =T8 -> unc | V8: =U8 -> unc | W8: =V8 -> unc | X8: =W8 -> unc | Y8: =X8 -> unc | Z8: =Y8 -> unc | ... AU8: =AT8 -> unc
A9: =A8 -> LEAST_CNST | B9: 1 | C9: RSA | D9: Generator | E9: ocgt_gas | F9: conventional | L9: 0 | M9: 0 | N9: 0 | O9: 0 | P9: 0 | Q9: unc | R9: unc | S9: =R9 -> unc | T9: =S9 -> unc | U9: =T9 -> unc | V9: =U9 -> unc | W9: =V9 -> unc | X9: =W9 -> unc | Y9: =X9 -> unc | Z9: =Y9 -> unc | ... AU9: =AT9 -> unc
