Workbook

Sheet fixed_generators
A1: scenario | B1: station_name | C1: parameter | D1: 2019 | E1: 2020 | F1: =E1+1 -> 2021 | G1: =F1+1 -> 2022 | H1: =G1+1 -> 2023 | I1: =H1+1 -> 2024 | J1: =I1+1 -> 2025 | K1: =J1+1 -> 2026 | L1: =K1+1 -> 2027 | M1: =L1+1 -> 2028 | ... AS1: =AR1+1 -> 2060
A2: ME_IRP23 | B2: variable_coal | C2: fuel_price (R/GJ) | J2: 37.741118 | K2: 41.652043 | L2: 46.571714 | M2: 49.303235 | N2: 52.352593 | O2: 55.610825 | P2: =O2 -> 55.610825 | Q2: =P2 -> 55.610825 | R2: =Q2 -> 55.610825 | S2: =R2 -> 55.610825 | T2: =S2 -> 55.610825 | U2: =T2 -> 55.610825 | V2: =U2 -> 55.610825 | W2: =V2 -> 55.610825 | ... AS2: =AR2 -> 55.610825
A3: =A2 -> ME_IRP23 | B3: variable_diesel | C3: fuel_price (R/GJ) | D3: 816 | E3: 816 | F3: 816 | G3: 816 | H3: 816 | I3: 816 | J3: 864.96 | K3: 864.96 | L3: 864.96 | M3: 864.96 | N3: 864.96 | O3: 864.96 | P3: 864.96 | Q3: 864.96 | R3: 864.96 | S3: 864.96 | T3: 864.96 | U3: 864.96 | V3: 864.96 | W3: 864.96 | X3: 864.96 | Y3: 864.96 | Z3: 864.96 | AA3: 864.96 | AB3: 864.96 | AC3: 864.96 | AD3: 864.96 | AE3: 864.96 | AF3: 864.96 | AG3: 864.96 | AH3: 864.96 | AI3: 864.96 | AJ3: =AI3 -> 864.96 | AK3: =AJ3 -> 864.96 | AL3: =AK3 -> 864.96 | AM3: =AL3 -> 864.96 | AN3: =AM3 -> 864.96 | AO3: =AN3 -> 864.96 | AP3: =AO3 -> 864.96 | AQ3: =AP3 -> 864.96 | ... AS3: =AR3 -> 864.96
A4: HIGH_PMR1 | B4: variable_coal | C4: fuel_price (R/GJ) | J4: 37.741118 | K4: 41.652043 | L4: 46.571714 | M4: 49.303235 | N4: 52.352593 | O4: 55.610825 | P4: =O4 -> 55.610825 | Q4: =P4 -> 55.610825 | R4: =Q4 -> 55.610825 | S4: =R4 -> 55.610825 | T4: =S4 -> 55.610825 | U4: =T4 -> 55.610825 | V4: =U4 -> 55.610825 | W4: =V4 -> 55.610825 | ... AS4: =AR4 -> 55.610825
A5: =A4 -> HIGH_PMR1 | B5: variable_diesel | C5: fuel_price (R/GJ) | D5: 816 | E5: 816 | F5: 816 | G5: 816 | H5: 816 | I5: 816 | J5: =extendable_generators!J2 -> 429.64 | K5: =extendable_generators!K2 -> 471.39 | L5: =extendable_generators!L2 -> 513.07 | M5: =extendable_generators!M2 -> 558.9 | N5: =extendable_generators!N2 -> 606.11 | O5: =extendable_generators!O2 -> 611.09 | P5: =extendable_generators!P2 -> 616.36 | Q5: =extendable_generators!Q2 -> 615.87 | ... AS5: =extendable_generators!AS2 -> 655.8
A6: =A5 -> HIGH_PMR1 | B6: low_group | C6: fuel_price (R/GJ) | J6: =0.74*J4 -> 27.928428 | K6: =0.74*K4 -> 30.822512 | L6: =0.74*L4 -> 34.463068 | M6: =0.74*M4 -> 36.484394 | N6: =0.74*N4 -> 38.740919 | O6: =0.74*O4 -> 41.15201 | P6: =0.74*P4 -> 41.15201 | Q6: =0.74*Q4 -> 41.15201 | ... AS6: =0.74*AS4 -> 41.15201
A7: =A8 -> HIGH_PMR1 | B7: med_group | C7: fuel_price (R/GJ) | J7: =1.06*J4 -> 40.005585 | K7: =1.06*K4 -> 44.151166 | L7: =1.06*L4 -> 49.366017 | M7: =1.06*M4 -> 52.261429 | N7: =1.06*N4 -> 55.493749 | O7: =1.06*O4 -> 58.947474 | P7: =1.06*P4 -> 58.947474 | Q7: =1.06*Q4 -> 58.947474 | ... AS7: =1.06*AS4 -> 58.947474
A8: =A6 -> HIGH_PMR1 | B8: high_group | C8: fuel_price (R/GJ) | J8: =1.28*J4 -> 48.308631 | K8: =1.28*K4 -> 53.314616 | L8: =1.28*L4 -> 59.611794 | M8: =1.28*M4 -> 63.10814 | N8: =1.28*N4 -> 67.011319 | O8: =1.28*O4 -> 71.181856 | P8: =1.28*P4 -> 71.181856 | Q8: =1.28*Q4 -> 71.181856 | ... AS8: =1.28*AS4 -> 71.181856
A9: BASE_PMR1 | B9: variable_coal | C9: fuel_price (R/GJ) | J9: 37.741118 | K9: 41.652043 | L9: 46.571714 | M9: 49.303235 | N9: 52.352593 | O9: 55.610825 | P9: =O9 -> 55.610825 | Q9: =P9 -> 55.610825 | R9: =Q9 -> 55.610825 | S9: =R9 -> 55.610825 | T9: =S9 -> 55.610825 | U9: =T9 -> 55.610825 | V9: =U9 -> 55.610825 | W9: =V9 -> 55.610825 | ... AS9: =AR9 -> 55.610825
A10: =A9 -> BASE_PMR1 | B10: variable_diesel | C10: fuel_price (R/GJ) | D10: 816 | E10: 816 | F10: 816 | G10: 816 | H10: 816 | I10: 816 | J10: =extendable_generators!J14 -> 396.72 | K10: =extendable_generators!K14 -> 405.87 | L10: =extendable_generators!L14 -> 415.35 | M10: =extendable_generators!M14 -> 425.96 | N10: =extendable_generators!N14 -> 437.53 | O10: =extendable_generators!O14 -> 440.21 | P10: =extendable_generators!P14 -> 442.39 | Q10: =extendable_generators!Q14 -> 445.58 | ... AS10: =extendable_generators!AS14 -> 483.6
A11: =A10 -> BASE_PMR1 | B11: low_group | C11: fuel_price (R/GJ) | J11: =0.74*J9 -> 27.928428 | K11: =0.74*K9 -> 30.822512 | L11: =0.74*L9 -> 34.463068 | M11: =0.74*M9 -> 36.484394 | N11: =0.74*N9 -> 38.740919 | O11: =0.74*O9 -> 41.15201 | P11: =0.74*P9 -> 41.15201 | Q11: =0.74*Q9 -> 41.15201 | ... AS11: =0.74*AS9 -> 41.15201
A12: =A11 -> BASE_PMR1 | B12: med_group | C12: fuel_price (R/GJ) | J12: =1.06*J9 -> 40.005585 | K12: =1.06*K9 -> 44.151166 | L12: =1.06*L9 -> 49.366017 | M12: =1.06*M9 -> 52.261429 | N12: =1.06*N9 -> 55.493749 | O12: =1.06*O9 -> 58.947474 | P12: =1.06*P9 -> 58.947474 | Q12: =1.06*Q9 -> 58.947474 | ... AS12: =1.06*AS9 -> 58.947474
A13: =A12 -> BASE_PMR1 | B13: high_group | C13: fuel_price (R/GJ) | J13: =1.28*J9 -> 48.308631 | K13: =1.28*K9 -> 53.314616 | L13: =1.28*L9 -> 59.611794 | M13: =1.28*M9 -> 63.10814 | N13: =1.28*N9 -> 67.011319 | O13: =1.28*O9 -> 71.181856 | P13: =1.28*P9 -> 71.181856 | Q13: =1.28*Q9 -> 71.181856 | ... AS13: =1.28*AS9 -> 71.181856
A14: LOW_PMR1 | B14: variable_coal | C14: fuel_price (R/GJ) | J14: 37.741118 | K14: 41.652043 | L14: 46.571714 | M14: 49.303235 | N14: 52.352593 | O14: 55.610825 | P14: =O14 -> 55.610825 | Q14: =P14 -> 55.610825 | R14: =Q14 -> 55.610825 | S14: =R14 -> 55.610825 | T14: =S14 -> 55.610825 | U14: =T14 -> 55.610825 | V14: =U14 -> 55.610825 | W14: =V14 -> 55.610825 | ... AS14: =AR14 -> 55.610825
A15: =A14 -> LOW_PMR1 | B15: variable_diesel | C15: fuel_price (R/GJ) | D15: 816 | E15: 816 | F15: 816 | G15: 816 | H15: 816 | I15: 816 | J15: =extendable_generators!J26 -> 380.19 | K15: =extendable_generators!K26 -> 372.37 | L15: =extendable_generators!L26 -> 364.35 | M15: =extendable_generators!M26 -> 358.54 | N15: =extendable_generators!N26 -> 352.2 | O15: =extendable_generators!O26 -> 354.57 | P15: =extendable_generators!P26 -> 356.83 | Q15: =extendable_generators!Q26 -> 359.66 | ... AS15: =extendable_generators!AS26 -> 386.45
A16: =A15 -> LOW_PMR1 | B16: low_group | C16: fuel_price (R/GJ) | J16: =0.74*J14 -> 27.928428 | K16: =0.74*K14 -> 30.822512 | L16: =0.74*L14 -> 34.463068 | M16: =0.74*M14 -> 36.484394 | N16: =0.74*N14 -> 38.740919 | O16: =0.74*O14 -> 41.15201 | P16: =0.74*P14 -> 41.15201 | Q16: =0.74*Q14 -> 41.15201 | ... AS16: =0.74*AS14 -> 41.15201
A17: =A16 -> LOW_PMR1 | B17: med_group | C17: fuel_price (R/GJ) | J17: =1.06*J14 -> 40.005585 | K17: =1.06*K14 -> 44.151166 | L17: =1.06*L14 -> 49.366017 | M17: =1.06*M14 -> 52.261429 | N17: =1.06*N14 -> 55.493749 | O17: =1.06*O14 -> 58.947474 | P17: =1.06*P14 -> 58.947474 | Q17: =1.06*Q14 -> 58.947474 | ... AS17: =1.06*AS14 -> 58.947474
A18: =A17 -> LOW_PMR1 | B18: high_group | C18: fuel_price (R/GJ) | J18: =1.28*J14 -> 48.308631 | K18: =1.28*K14 -> 53.314616 | L18: =1.28*L14 -> 59.611794 | M18: =1.28*M14 -> 63.10814 | N18: =1.28*N14 -> 67.011319 | O18: =1.28*O14 -> 71.181856 | P18: =1.28*P14 -> 71.181856 | Q18: =1.28*Q14 -> 71.181856 | ... AS18: =1.28*AS14 -> 71.181856
A19: HIGH_PMR1b | B19: variable_coal | C19: fuel_price (R/GJ) | J19: 37.741118 | K19: 41.652043 | L19: 46.571714 | M19: 49.303235 | N19: 52.352593 | O19: 55.610825 | P19: =O19 -> 55.610825 | Q19: =P19 -> 55.610825 | R19: =Q19 -> 55.610825 | S19: =R19 -> 55.610825 | T19: =S19 -> 55.610825 | U19: =T19 -> 55.610825 | V19: =U19 -> 55.610825 | W19: =V19 -> 55.610825 | ... AS19: =AR19 -> 55.610825
A20: =A19 -> HIGH_PMR1b | B20: variable_diesel | C20: fuel_price (R/GJ) | D20: 816 | E20: 816 | F20: 816 | G20: 816 | H20: 816 | I20: 816 | J20: =extendable_generators!J62 -> 388.87 | K20: =extendable_generators!K62 -> 404.1 | L20: =extendable_generators!L62 -> 418.4 | M20: =extendable_generators!M62 -> 432.19 | N20: =extendable_generators!N62 -> 446.49 | O20: =extendable_generators!O62 -> 462.62 | P20: =extendable_generators!P62 -> 468.14 | Q20: =extendable_generators!Q62 -> 468.5 | ... AS20: =extendable_generators!AS62 -> 544
A21: =A20 -> HIGH_PMR1b | B21: low_group | C21: fuel_price (R/GJ) | J21: =0.74*J19 -> 27.928428 | K21: =0.74*K19 -> 30.822512 | L21: =0.74*L19 -> 34.463068 | M21: =0.74*M19 -> 36.484394 | N21: =0.74*N19 -> 38.740919 | O21: =0.74*O19 -> 41.15201 | P21: =0.74*P19 -> 41.15201 | Q21: =0.74*Q19 -> 41.15201 | ... AS21: =0.74*AS19 -> 41.15201
A22: =A23 -> HIGH_PMR1b | B22: med_group | C22: fuel_price (R/GJ) | J22: =1.06*J19 -> 40.005585 | K22: =1.06*K19 -> 44.151166 | L22: =1.06*L19 -> 49.366017 | M22: =1.06*M19 -> 52.261429 | N22: =1.06*N19 -> 55.493749 | O22: =1.06*O19 -> 58.947474 | P22: =1.06*P19 -> 58.947474 | Q22: =1.06*Q19 -> 58.947474 | ... AS22: =1.06*AS19 -> 58.947474
A23: =A21 -> HIGH_PMR1b | B23: high_group | C23: fuel_price (R/GJ) | J23: =1.28*J19 -> 48.308631 | K23: =1.28*K19 -> 53.314616 | L23: =1.28*L19 -> 59.611794 | M23: =1.28*M19 -> 63.10814 | N23: =1.28*N19 -> 67.011319 | O23: =1.28*O19 -> 71.181856 | P23: =1.28*P19 -> 71.181856 | Q23: =1.28*Q19 -> 71.181856 | ... AS23: =1.28*AS19 -> 71.181856
A24: BASE_PMR1b | B24: variable_coal | C24: fuel_price (R/GJ) | J24: 37.741118 | K24: 41.652043 | L24: 46.571714 | M24: 49.303235 | N24: 52.352593 | O24: 55.610825 | P24: =O24 -> 55.610825 | Q24: =P24 -> 55.610825 | R24: =Q24 -> 55.610825 | S24: =R24 -> 55.610825 | T24: =S24 -> 55.610825 | U24: =T24 -> 55.610825 | V24: =U24 -> 55.610825 | W24: =V24 -> 55.610825 | ... AS24: =AR24 -> 55.610825
A25: =A24 -> BASE_PMR1b | B25: variable_diesel | C25: fuel_price (R/GJ) | D25: 816 | E25: 816 | F25: 816 | G25: 816 | H25: 816 | I25: 816 | J25: =extendable_generators!J74 -> 388.87 | K25: =extendable_generators!K74 -> 388.6 | L25: =extendable_generators!L74 -> 386.77 | M25: =extendable_generators!M74 -> 384.37 | N25: =extendable_generators!N74 -> 382.13 | O25: =extendable_generators!O74 -> 381.53 | P25: =extendable_generators!P74 -> 383.6 | Q25: =extendable_generators!Q74 -> 381.66 | ... AS25: =extendable_generators!AS74 -> 424
A26: =A25 -> BASE_PMR1b | B26: low_group | C26: fuel_price (R/GJ) | J26: =0.74*J24 -> 27.928428 | K26: =0.74*K24 -> 30.822512 | L26: =0.74*L24 -> 34.463068 | M26: =0.74*M24 -> 36.484394 | N26: =0.74*N24 -> 38.740919 | O26: =0.74*O24 -> 41.15201 | P26: =0.74*P24 -> 41.15201 | Q26: =0.74*Q24 -> 41.15201 | ... AS26: =0.74*AS24 -> 41.15201
A27: =A26 -> BASE_PMR1b | B27: med_group | C27: fuel_price (R/GJ) | J27: =1.06*J24 -> 40.005585 | K27: =1.06*K24 -> 44.151166 | L27: =1.06*L24 -> 49.366017 | M27: =1.06*M24 -> 52.261429 | N27: =1.06*N24 -> 55.493749 | O27: =1.06*O24 -> 58.947474 | P27: =1.06*P24 -> 58.947474 | Q27: =1.06*Q24 -> 58.947474 | ... AS27: =1.06*AS24 -> 58.947474
A28: =A27 -> BASE_PMR1b | B28: high_group | C28: fuel_price (R/GJ) | J28: =1.28*J24 -> 48.308631 | K28: =1.28*K24 -> 53.314616 | L28: =1.28*L24 -> 59.611794 | M28: =1.28*M24 -> 63.10814 | N28: =1.28*N24 -> 67.011319 | O28: =1.28*O24 -> 71.181856 | P28: =1.28*P24 -> 71.181856 | Q28: =1.28*Q24 -> 71.181856 | ... AS28: =1.28*AS24 -> 71.181856
A29: LOW_PMR1b | B29: variable_coal | C29: fuel_price (R/GJ) | J29: 37.741118 | K29: 41.652043 | L29: 46.571714 | M29: 49.303235 | N29: 52.352593 | O29: 55.610825 | P29: =O29 -> 55.610825 | Q29: =P29 -> 55.610825 | R29: =Q29 -> 55.610825 | S29: =R29 -> 55.610825 | T29: =S29 -> 55.610825 | U29: =T29 -> 55.610825 | V29: =U29 -> 55.610825 | W29: =V29 -> 55.610825 | ... AS29: =AR29 -> 55.610825
A30: =A29 -> LOW_PMR1b | B30: variable_diesel | C30: fuel_price (R/GJ) | D30: 816 | E30: 816 | F30: 816 | G30: 816 | H30: 816 | I30: 816 | J30: =extendable_generators!J86 -> 388.87 | K30: =extendable_generators!K86 -> 372.94 | L30: =extendable_generators!L86 -> 356.79 | M30: =extendable_generators!M86 -> 341.89 | N30: =extendable_generators!N86 -> 326.08 | O30: =extendable_generators!O86 -> 311.33 | P30: =extendable_generators!P86 -> 313.23 | Q30: =extendable_generators!Q86 -> 312.72 | ... AS30: =extendable_generators!AS86 -> 345
A31: =A30 -> LOW_PMR1b | B31: low_group | C31: fuel_price (R/GJ) | J31: =0.74*J29 -> 27.928428 | K31: =0.74*K29 -> 30.822512 | L31: =0.74*L29 -> 34.463068 | M31: =0.74*M29 -> 36.484394 | N31: =0.74*N29 -> 38.740919 | O31: =0.74*O29 -> 41.15201 | P31: =0.74*P29 -> 41.15201 | Q31: =0.74*Q29 -> 41.15201 | ... AS31: =0.74*AS29 -> 41.15201
A32: =A31 -> LOW_PMR1b | B32: med_group | C32: fuel_price (R/GJ) | J32: =1.06*J29 -> 40.005585 | K32: =1.06*K29 -> 44.151166 | L32: =1.06*L29 -> 49.366017 | M32: =1.06*M29 -> 52.261429 | N32: =1.06*N29 -> 55.493749 | O32: =1.06*O29 -> 58.947474 | P32: =1.06*P29 -> 58.947474 | Q32: =1.06*Q29 -> 58.947474 | ... AS32: =1.06*AS29 -> 58.947474
A33: =A32 -> LOW_PMR1b | B33: high_group | C33: fuel_price (R/GJ) | J33: =1.28*J29 -> 48.308631 | K33: =1.28*K29 -> 53.314616 | L33: =1.28*L29 -> 59.611794 | M33: =1.28*M29 -> 63.10814 | N33: =1.28*N29 -> 67.011319 | O33: =1.28*O29 -> 71.181856 | P33: =1.28*P29 -> 71.181856 | Q33: =1.28*Q29 -> 71.181856 | ... AS33: =1.28*AS29 -> 71.181856
A34: CALC | B34: Komati | C34: ratio_vs_avg | J34: 1.28
A35: CALC | B35: Tutuka | C35: ratio_vs_avg | J35: 1.28
A36: CALC | B36: Matla | C36: ratio_vs_avg | J36: 1.28
A37: CALC | B37: Kusile | C37: ratio_vs_avg | J37: 1.28
A38: CALC | B38: Grootvlei | C38: ratio_vs_avg | J38: 1.28
A39: CALC | B39: Camden | C39: ratio_vs_avg | J39: 1.28
A40: CALC | B40: Kriel | C40: ratio_vs_avg | J40: 1.28
...

Sheet extendable_generators
A1: scenario | B1: station_name | C1: parameter | D1: 2019 | E1: 2020 | F1: =E1+1 -> 2021 | G1: =F1+1 -> 2022 | H1: =G1+1 -> 2023 | I1: =H1+1 -> 2024 | J1: =I1+1 -> 2025 | K1: =J1+1 -> 2026 | L1: =K1+1 -> 2027 | M1: =L1+1 -> 2028 | ... AS1: =AR1+1 -> 2060
A2: HIGH_PMR1 | B2: ocgt_diesel | C2: R/GJ | D2: 667.51684 | E2: 669.91818 | F2: 670.59782 | G2: 676.03509 | H2: 680.63895 | I2: 685.52927 | J2: 429.64 | K2: 471.39 | L2: 513.07 | M2: 558.9 | N2: 606.11 | O2: 611.09 | P2: 616.36 | Q2: 615.87 | R2: 619.91 | S2: 627.52 | T2: 629.52 | U2: 629.8 | V2: 636.18 | W2: 629.96 | X2: 631.33 | Y2: 632.86 | Z2: 637.49 | AA2: 640.96 | AB2: 641.74 | AC2: 644.67 | AD2: 643.6 | AE2: 644.79 | AF2: 647.71 | AG2: 653.19 | AH2: 654.28 | AI2: 655.8 | AJ2: 655.8 | AK2: 655.8 | AL2: 655.8 | AM2: 655.8 | AN2: 655.8 | AO2: 655.8 | AP2: 655.8 | AQ2: 655.8 | AR2: 655.8 | AS2: 655.8
A3: =A2 -> HIGH_PMR1 | B3: ocgt_diesel_emg | C3: R/GJ | D3: 667.51684 | E3: 669.91818 | F3: 670.59782 | G3: 676.03509 | H3: 680.63895 | I3: 685.52927 | J3: 429.64 | K3: 471.39 | L3: 513.07 | M3: 558.9 | N3: 606.11 | O3: 611.09 | P3: 616.36 | Q3: 615.87 | R3: 619.91 | S3: 627.52 | T3: 629.52 | U3: 629.8 | V3: 636.18 | W3: 629.96 | X3: 631.33 | Y3: 632.86 | Z3: 637.49 | AA3: 640.96 | AB3: 641.74 | AC3: 644.67 | AD3: 643.6 | AE3: 644.79 | AF3: 647.71 | AG3: 653.19 | AH3: 654.28 | AI3: 655.8 | AJ3: 655.8 | AK3: 655.8 | AL3: 655.8 | AM3: 655.8 | AN3: 655.8 | AO3: 655.8 | AP3: 655.8 | AQ3: 655.8 | AR3: 655.8 | AS3: 655.8
A4: =A3 -> HIGH_PMR1 | B4: ocgt_gas | C4: R/GJ | D4: 184 | E4: 184 | F4: 184 | G4: 184 | H4: 184 | I4: 184 | J4: 244.67 | K4: 271.33 | L4: 297.95 | M4: 327.22 | N4: 357.37 | O4: 360.55 | P4: 363.92 | Q4: 363.61 | R4: 366.18 | S4: 371.04 | T4: 372.32 | U4: 372.5 | V4: 376.58 | W4: 372.6 | X4: 373.48 | Y4: 374.46 | Z4: 377.41 | AA4: 379.63 | AB4: 380.13 | AC4: 382 | AD4: 381.32 | AE4: 382.08 | AF4: 383.94 | AG4: 387.44 | AH4: 388.14 | AI4: 389.1 | AJ4: =AI4 -> 389.1 | AK4: =AJ4 -> 389.1 | AL4: =AK4 -> 389.1 | AM4: =AL4 -> 389.1 | AN4: =AM4 -> 389.1 | AO4: =AN4 -> 389.1 | AP4: =AO4 -> 389.1 | AQ4: =AP4 -> 389.1 | ... AS4: =AR4 -> 389.1
A5: =A4 -> HIGH_PMR1 | B5: ocgt_gas_h2_40 | C5: R/GJ | D5: 184 | E5: 184 | F5: 184 | G5: 184 | H5: 184 | I5: 184 | J5: =J4 -> 244.67 | K5: =K4 -> 271.33 | L5: =L4 -> 297.95 | M5: =M4 -> 327.22 | N5: =N4 -> 357.37 | O5: =O4 -> 360.55 | P5: =P4 -> 363.92 | Q5: =Q4 -> 363.61 | ... X5: =X4 -> 373.48 | Y5: =Y2 -> 632.86 | Z5: =Z2 -> 637.49 | AA5: =AA2 -> 640.96 | AB5: =AB2 -> 641.74 | AC5: =AC2 -> 644.67 | AD5: =AD2 -> 643.6 | AE5: =AE2 -> 644.79 | AF5: =AF2 -> 647.71 | ... AS5: =AS2 -> 655.8
A6: =A5 -> HIGH_PMR1 | B6: ocgt_gas_h2_45 | C6: R/GJ | D6: 184 | E6: 184 | F6: 184 | G6: 184 | H6: 184 | I6: 184 | J6: =J4 -> 244.67 | K6: =K4 -> 271.33 | L6: =L4 -> 297.95 | M6: =M4 -> 327.22 | N6: =N4 -> 357.37 | O6: =O4 -> 360.55 | P6: =P4 -> 363.92 | Q6: =Q4 -> 363.61 | ... AC6: =AC4 -> 382 | AD6: =AD2 -> 643.6 | AE6: =AE2 -> 644.79 | AF6: =AF2 -> 647.71 | AG6: =AG2 -> 653.19 | AH6: =AH2 -> 654.28 | AI6: =AI2 -> 655.8 | AJ6: =AJ2 -> 655.8 | AK6: =AK2 -> 655.8 | ... AS6: =AS2 -> 655.8
A7: =A6 -> HIGH_PMR1 | B7: ocgt_gas_h2_50 | C7: R/GJ | D7: 184 | E7: 184 | F7: 184 | G7: 184 | H7: 184 | I7: 184 | J7: =J4 -> 244.67 | K7: =K4 -> 271.33 | L7: =L4 -> 297.95 | M7: =M4 -> 327.22 | N7: =N4 -> 357.37 | O7: =O4 -> 360.55 | P7: =P4 -> 363.92 | Q7: =Q4 -> 363.61 | ... AH7: =AH4 -> 388.14 | AI7: =AI2 -> 655.8 | AJ7: =AJ2 -> 655.8 | AK7: =AK2 -> 655.8 | AL7: =AL2 -> 655.8 | AM7: =AM2 -> 655.8 | AN7: =AN2 -> 655.8 | AO7: =AO2 -> 655.8 | AP7: =AP2 -> 655.8 | ... AS7: =AS2 -> 655.8
A8: =A7 -> HIGH_PMR1 | B8: ocgt_gas_h2_55 | C8: R/GJ | D8: 184 | E8: 184 | F8: 184 | G8: 184 | H8: 184 | I8: 184 | J8: =J4 -> 244.67 | K8: =K4 -> 271.33 | L8: =L4 -> 297.95 | M8: =M4 -> 327.22 | N8: =N4 -> 357.37 | O8: =O4 -> 360.55 | P8: =P4 -> 363.92 | Q8: =Q4 -> 363.61 | ... AM8: =AM4 -> 389.1 | AN8: =AN7 -> 655.8 | AO8: =AO7 -> 655.8 | AP8: =AP7 -> 655.8 | AQ8: =AQ7 -> 655.8 | AR8: =AR7 -> 655.8 | AS8: =AS7 -> 655.8
A9: =A8 -> HIGH_PMR1 | B9: ocgt_gas_h2_60 | C9: R/GJ | D9: 184 | E9: 184 | F9: 184 | G9: 184 | H9: 184 | I9: 184 | J9: =J4 -> 244.67 | K9: =K4 -> 271.33 | L9: =L4 -> 297.95 | M9: =M4 -> 327.22 | N9: =N4 -> 357.37 | O9: =O4 -> 360.55 | P9: =P4 -> 363.92 | Q9: =Q4 -> 363.61 | ... AR9: =AR4 -> 389.1 | AS9: =AS7 -> 655.8
A10: =A9 -> HIGH_PMR1 | B10: coal | C10: R/GJ | D10: 45.18 | E10: 45.18 | F10: 45.18 | G10: 45.18 | H10: 45.18 | I10: 45.18 | J10: 45.18 | K10: 45.18 | L10: 45.18 | M10: 45.18 | N10: 45.18 | O10: 45.18 | P10: 45.18 | Q10: 45.18 | R10: 45.18 | S10: 45.18 | T10: 45.18 | U10: 45.18 | V10: 45.18 | W10: 45.18 | X10: 45.18 | Y10: 45.18 | Z10: 45.18 | AA10: 45.18 | AB10: 45.18 | AC10: 45.18 | AD10: 45.18 | AE10: 45.18 | AF10: 45.18 | AG10: 45.18 | AH10: 45.18 | AI10: 45.18 | AJ10: =AI10 -> 45.18 | AK10: 45 | AL10: 45 | AM10: 45 | AN10: 45 | AO10: 45 | AP10: 45 | AQ10: 45 | AR10: 45 | AS10: 45
A11: =A10 -> HIGH_PMR1 | B11: nuclear | C11: R/GJ | D11: 18 | E11: 18 | F11: 18 | G11: 18 | H11: 18 | I11: 18 | J11: 18 | K11: 18 | L11: 18 | M11: 18 | N11: 18 | O11: 18 | P11: 18 | Q11: 18 | R11: 18 | S11: 18 | T11: 18 | U11: 18 | V11: 18 | W11: 18 | X11: 18 | Y11: 18 | Z11: 18 | AA11: 18 | AB11: 18 | AC11: 18 | AD11: 18 | AE11: 18 | AF11: 18 | AG11: 18 | AH11: 18 | AI11: 18 | AJ11: =AI11 -> 18 | AK11: =AJ11 -> 18 | AL11: =AK11 -> 18 | AM11: =AL11 -> 18 | AN11: =AM11 -> 18 | AO11: =AN11 -> 18 | AP11: =AO11 -> 18 | AQ11: =AP11 -> 18 | ... AS11: =AR11 -> 18
A12: =A11 -> HIGH_PMR1 | B12: solar_csp | C12: R/GJ | D12: 0 | E12: 0 | F12: 0 | G12: 0 | H12: 0 | I12: 0 | J12: 0 | K12: 0 | L12: 0 | M12: 0 | N12: 0 | O12: 0 | P12: 0 | Q12: 0 | R12: 0 | S12: 0 | T12: 0 | U12: 0 | V12: 0 | W12: 0 | X12: 0 | Y12: 0 | Z12: 0 | AA12: 0 | AB12: 0 | AC12: 0 | AD12: 0 | AE12: 0 | AF12: 0 | AG12: 0 | AH12: 0 | AI12: 0 | AJ12: =AI12 -> 0 | AK12: 0 | AL12: 0 | AM12: 0 | AN12: 0 | AO12: 0 | AP12: 0 | AQ12: 0 | AR12: 0 | AS12: 0
A13: =A12 -> HIGH_PMR1 | B13: ccgt_steam | C13: R/GJ | D13: 0 | E13: 0 | F13: 0 | G13: 0 | H13: 0 | I13: 0 | J13: 0 | K13: 0 | L13: 0 | M13: 0 | N13: 0 | O13: 0 | P13: 0 | Q13: 0 | R13: 0 | S13: 0 | T13: 0 | U13: 0 | V13: 0 | W13: 0 | X13: 0 | Y13: 0 | Z13: 0 | AA13: 0 | AB13: 0 | AC13: 0 | AD13: 0 | AE13: 0 | AF13: 0 | AG13: 0 | AH13: 0 | AI13: 0 | AJ13: =AI13 -> 0 | AK13: 0 | AL13: 0 | AM13: 0 | AN13: 0 | AO13: 0 | AP13: 0 | AQ13: 0 | AR13: 0 | AS13: 0
A14: BASE_PMR1 | B14: ocgt_diesel | C14: R/GJ | D14: 506.07771 | E14: 509.25357 | F14: 510.86624 | G14: 513.0464 | H14: 515.29938 | I14: 517.9345 | J14: 396.72 | K14: 405.87 | L14: 415.35 | M14: 425.96 | N14: 437.53 | O14: 440.21 | P14: 442.39 | Q14: 445.58 | R14: 447.37 | S14: 450.04 | T14: 453.37 | U14: 455.66 | V14: 458.2 | W14: 460.28 | X14: 462.36 | Y14: 464.39 | Z14: 466.51 | AA14: 468.23 | AB14: 469.7 | AC14: 471.57 | AD14: 472.95 | AE14: 475.98 | AF14: 477.6 | AG14: 479.89 | AH14: 482.55 | AI14: 483.6 | AJ14: 483.6 | AK14: 483.6 | AL14: 483.6 | AM14: 483.6 | AN14: 483.6 | AO14: 483.6 | AP14: 483.6 | AQ14: 483.6 | AR14: 483.6 | AS14: 483.6
A15: =A14 -> BASE_PMR1 | B15: ocgt_diesel_emg | C15: R/GJ | D15: 506.07771 | E15: 509.25357 | F15: 510.86624 | G15: 513.0464 | H15: 515.29938 | I15: 517.9345 | J15: 396.72 | K15: 405.87 | L15: 415.35 | M15: 425.96 | N15: 437.53 | O15: 440.21 | P15: 442.39 | Q15: 445.58 | R15: 447.37 | S15: 450.04 | T15: 453.37 | U15: 455.66 | V15: 458.2 | W15: 460.28 | X15: 462.36 | Y15: 464.39 | Z15: 466.51 | AA15: 468.23 | AB15: 469.7 | AC15: 471.57 | AD15: 472.95 | AE15: 475.98 | AF15: 477.6 | AG15: 479.89 | AH15: 482.55 | AI15: 483.6 | AJ15: 483.6 | AK15: 483.6 | AL15: 483.6 | AM15: 483.6 | AN15: 483.6 | AO15: 483.6 | AP15: 483.6 | AQ15: 483.6 | AR15: 483.6 | AS15: 483.6
A16: =A15 -> BASE_PMR1 | B16: ocgt_gas | C16: R/GJ | D16: 272 | E16: 272 | F16: 272 | G16: 272 | H16: 272 | I16: 272 | J16: 223.65 | K16: 229.49 | L16: 235.54 | M16: 242.32 | N16: 249.71 | O16: 251.42 | P16: 252.81 | Q16: 254.85 | R16: 255.99 | S16: 257.7 | T16: 259.83 | U16: 261.29 | V16: 262.91 | W16: 264.24 | X16: 265.56 | Y16: 266.86 | Z16: 268.22 | AA16: 269.32 | AB16: 270.25 | AC16: 271.45 | AD16: 272.33 | AE16: 274.26 | AF16: 275.3 | AG16: 276.76 | AH16: 278.46 | AI16: 279.13 | AJ16: =AI16 -> 279.13 | AK16: =AJ16 -> 279.13 | AL16: =AK16 -> 279.13 | AM16: =AL16 -> 279.13 | AN16: =AM16 -> 279.13 | AO16: =AN16 -> 279.13 | AP16: =AO16 -> 279.13 | AQ16: =AP16 -> 279.13 | ... AS16: =AR16 -> 279.13
A17: =A16 -> BASE_PMR1 | B17: ocgt_gas_h2_40 | C17: R/GJ | D17: 272 | E17: 272 | F17: 272 | G17: 272 | H17: 272 | I17: 272 | J17: =J16 -> 223.65 | K17: =K16 -> 229.49 | L17: =L16 -> 235.54 | M17: =M16 -> 242.32 | N17: =N16 -> 249.71 | O17: =O16 -> 251.42 | P17: =P16 -> 252.81 | Q17: =Q16 -> 254.85 | ... X17: =X16 -> 265.56 | Y17: =Y14 -> 464.39 | Z17: =Z14 -> 466.51 | AA17: =AA14 -> 468.23 | AB17: =AB14 -> 469.7 | AC17: =AC14 -> 471.57 | AD17: =AD14 -> 472.95 | AE17: =AE14 -> 475.98 | AF17: =AF14 -> 477.6 | ... AS17: =AS14 -> 483.6
A18: =A17 -> BASE_PMR1 | B18: ocgt_gas_h2_45 | C18: R/GJ | D18: 272 | E18: 272 | F18: 272 | G18: 272 | H18: 272 | I18: 272 | J18: =J16 -> 223.65 | K18: =K16 -> 229.49 | L18: =L16 -> 235.54 | M18: =M16 -> 242.32 | N18: =N16 -> 249.71 | O18: =O16 -> 251.42 | P18: =P16 -> 252.81 | Q18: =Q16 -> 254.85 | ... AC18: =AC16 -> 271.45 | AD18: =AD14 -> 472.95 | AE18: =AE14 -> 475.98 | AF18: =AF14 -> 477.6 | AG18: =AG14 -> 479.89 | AH18: =AH14 -> 482.55 | AI18: =AI14 -> 483.6 | AJ18: =AJ14 -> 483.6 | AK18: =AK14 -> 483.6 | ... AS18: =AS14 -> 483.6
A19: =A18 -> BASE_PMR1 | B19: ocgt_gas_h2_50 | C19: R/GJ | D19: 272 | E19: 272 | F19: 272 | G19: 272 | H19: 272 | I19: 272 | J19: =J16 -> 223.65 | K19: =K16 -> 229.49 | L19: =L16 -> 235.54 | M19: =M16 -> 242.32 | N19: =N16 -> 249.71 | O19: =O16 -> 251.42 | P19: =P16 -> 252.81 | Q19: =Q16 -> 254.85 | ... AH19: =AH16 -> 278.46 | AI19: =AI14 -> 483.6 | AJ19: =AJ14 -> 483.6 | AK19: =AK14 -> 483.6 | AL19: =AL14 -> 483.6 | AM19: =AM14 -> 483.6 | AN19: =AN14 -> 483.6 | AO19: =AO14 -> 483.6 | AP19: =AP14 -> 483.6 | ... AS19: =AS14 -> 483.6
A20: =A19 -> BASE_PMR1 | B20: ocgt_gas_h2_55 | C20: R/GJ | D20: 272 | E20: 272 | F20: 272 | G20: 272 | H20: 272 | I20: 272 | J20: =J16 -> 223.65 | K20: =K16 -> 229.49 | L20: =L16 -> 235.54 | M20: =M16 -> 242.32 | N20: =N16 -> 249.71 | O20: =O16 -> 251.42 | P20: =P16 -> 252.81 | Q20: =Q16 -> 254.85 | ... AM20: =AM16 -> 279.13 | AN20: =AN19 -> 483.6 | AO20: =AO19 -> 483.6 | AP20: =AP19 -> 483.6 | AQ20: =AQ19 -> 483.6 | AR20: =AR19 -> 483.6 | AS20: =AS19 -> 483.6
A21: =A20 -> BASE_PMR1 | B21: ocgt_gas_h2_60 | C21: R/GJ | D21: 272 | E21: 272 | F21: 272 | G21: 272 | H21: 272 | I21: 272 | J21: =J16 -> 223.65 | K21: =K16 -> 229.49 | L21: =L16 -> 235.54 | M21: =M16 -> 242.32 | N21: =N16 -> 249.71 | O21: =O16 -> 251.42 | P21: =P16 -> 252.81 | Q21: =Q16 -> 254.85 | ... AR21: =AR16 -> 279.13 | AS21: =AS14 -> 483.6
A22: =A21 -> BASE_PMR1 | B22: coal | C22: R/GJ | D22: 45.18 | E22: 45.18 | F22: 45.18 | G22: 45.18 | H22: 45.18 | I22: 45.18 | J22: 45.18 | K22: 45.18 | L22: 45.18 | M22: 45.18 | N22: 45.18 | O22: 45.18 | P22: 45.18 | Q22: 45.18 | R22: 45.18 | S22: 45.18 | T22: 45.18 | U22: 45.18 | V22: 45.18 | W22: 45.18 | X22: 45.18 | Y22: 45.18 | Z22: 45.18 | AA22: 45.18 | AB22: 45.18 | AC22: 45.18 | AD22: 45.18 | AE22: 45.18 | AF22: 45.18 | AG22: 45.18 | AH22: 45.18 | AI22: 45.18 | AJ22: =AI22 -> 45.18 | AK22: =AJ22 -> 45.18 | AL22: =AK22 -> 45.18 | AM22: =AL22 -> 45.18 | AN22: =AM22 -> 45.18 | AO22: =AN22 -> 45.18 | AP22: =AO22 -> 45.18 | AQ22: =AP22 -> 45.18 | ... AS22: =AR22 -> 45.18
A23: =A22 -> BASE_PMR1 | B23: nuclear | C23: R/GJ | D23: 18 | E23: 18 | F23: 18 | G23: 18 | H23: 18 | I23: 18 | J23: 18 | K23: 18 | L23: 18 | M23: 18 | N23: 18 | O23: 18 | P23: 18 | Q23: 18 | R23: 18 | S23: 18 | T23: 18 | U23: 18 | V23: 18 | W23: 18 | X23: 18 | Y23: 18 | Z23: 18 | AA23: 18 | AB23: 18 | AC23: 18 | AD23: 18 | AE23: 18 | AF23: 18 | AG23: 18 | AH23: 18 | AI23: 18 | AJ23: =AI23 -> 18 | AK23: =AJ23 -> 18 | AL23: =AK23 -> 18 | AM23: =AL23 -> 18 | AN23: =AM23 -> 18 | AO23: =AN23 -> 18 | AP23: =AO23 -> 18 | AQ23: =AP23 -> 18 | ... AS23: =AR23 -> 18
A24: =A23 -> BASE_PMR1 | B24: solar_csp | C24: R/GJ | D24: 0 | E24: 0 | F24: 0 | G24: 0 | H24: 0 | I24: 0 | J24: 0 | K24: 0 | L24: 0 | M24: 0 | N24: 0 | O24: 0 | P24: 0 | Q24: 0 | R24: 0 | S24: 0 | T24: 0 | U24: 0 | V24: 0 | W24: 0 | X24: 0 | Y24: 0 | Z24: 0 | AA24: 0 | AB24: 0 | AC24: 0 | AD24: 0 | AE24: 0 | AF24: 0 | AG24: 0 | AH24: 0 | AI24: 0 | AJ24: =AI24 -> 0 | AK24: 0 | AL24: 0 | AM24: 0 | AN24: 0 | AO24: 0 | AP24: 0 | AQ24: 0 | AR24: 0 | AS24: 0
A25: =A24 -> BASE_PMR1 | B25: ccgt_steam | C25: R/GJ | D25: 0 | E25: 0 | F25: 0 | G25: 0 | H25: 0 | I25: 0 | J25: 0 | K25: 0 | L25: 0 | M25: 0 | N25: 0 | O25: 0 | P25: 0 | Q25: 0 | R25: 0 | S25: 0 | T25: 0 | U25: 0 | V25: 0 | W25: 0 | X25: 0 | Y25: 0 | Z25: 0 | AA25: 0 | AB25: 0 | AC25: 0 | AD25: 0 | AE25: 0 | AF25: 0 | AG25: 0 | AH25: 0 | AI25: 0 | AJ25: =AI25 -> 0 | AK25: 0 | AL25: 0 | AM25: 0 | AN25: 0 | AO25: 0 | AP25: 0 | AQ25: 0 | AR25: 0 | AS25: 0
A26: LOW_PMR1 | B26: ocgt_diesel | C26: R/GJ | D26: 400.69668 | E26: 402.46947 | F26: 402.49144 | G26: 405.59713 | H26: 406.5107 | I26: 408.73353 | J26: 380.19 | K26: 372.37 | L26: 364.35 | M26: 358.54 | N26: 352.2 | O26: 354.57 | P26: 356.83 | Q26: 359.66 | R26: 361.8 | S26: 363.06 | T26: 365.73 | U26: 368.19 | V26: 370.21 | W26: 371.39 | X26: 373.3 | Y26: 372.78 | Z26: 373.9 | AA26: 374.81 | AB26: 375.57 | AC26: 377.42 | AD26: 378.15 | AE26: 381.35 | AF26: 381 | AG26: 383.49 | AH26: 384.2 | AI26: 386.45 | AJ26: 386.45 | AK26: 386.45 | AL26: 386.45 | AM26: 386.45 | AN26: 386.45 | AO26: 386.45 | AP26: 386.45 | AQ26: 386.45 | AR26: 386.45 | AS26: 386.45
A27: =A26 -> LOW_PMR1 | B27: ocgt_diesel_emg | C27: R/GJ | D27: 400.69668 | E27: 402.46947 | F27: 402.49144 | G27: 405.59713 | H27: 406.5107 | I27: 408.73353 | J27: 380.19 | K27: 372.37 | L27: 364.35 | M27: 358.54 | N27: 352.2 | O27: 354.57 | P27: 356.83 | Q27: 359.66 | R27: 361.8 | S27: 363.06 | T27: 365.73 | U27: 368.19 | V27: 370.21 | W27: 371.39 | X27: 373.3 | Y27: 372.78 | Z27: 373.9 | AA27: 374.81 | AB27: 375.57 | AC27: 377.42 | AD27: 378.15 | AE27: 381.35 | AF27: 381 | AG27: 383.49 | AH27: 384.2 | AI27: 386.45 | AJ27: 386.45 | AK27: 386.45 | AL27: 386.45 | AM27: 386.45 | AN27: 386.45 | AO27: 386.45 | AP27: 386.45 | AQ27: 386.45 | AR27: 386.45 | AS27: 386.45
A28: =A27 -> LOW_PMR1 | B28: ocgt_gas | C28: R/GJ | D28: 272 | E28: 272 | F28: 272 | G28: 272 | H28: 272 | I28: 272 | J28: 202.87 | K28: 197.88 | L28: 192.76 | M28: 189.04 | N28: 185 | O28: 186.51 | P28: 187.95 | Q28: 189.76 | R28: 191.13 | S28: 191.93 | T28: 193.64 | U28: 195.21 | V28: 196.5 | W28: 197.25 | X28: 198.47 | Y28: 198.14 | Z28: 198.86 | AA28: 199.43 | AB28: 199.92 | AC28: 201.1 | AD28: 201.57 | AE28: 203.61 | AF28: 203.39 | AG28: 204.98 | AH28: 205.43 | AI28: 206.87 | AJ28: =AI28 -> 206.87 | AK28: =AJ28 -> 206.87 | AL28: =AK28 -> 206.87 | AM28: =AL28 -> 206.87 | AN28: =AM28 -> 206.87 | AO28: =AN28 -> 206.87 | AP28: =AO28 -> 206.87 | AQ28: =AP28 -> 206.87 | ... AS28: =AR28 -> 206.87
A29: =A28 -> LOW_PMR1 | B29: ocgt_gas_h2_40 | C29: R/GJ | D29: 272 | E29: 272 | F29: 272 | G29: 272 | H29: 272 | I29: 272 | J29: =J28 -> 202.87 | K29: =K28 -> 197.88 | L29: =L28 -> 192.76 | M29: =M28 -> 189.04 | N29: =N28 -> 185 | O29: =O28 -> 186.51 | P29: =P28 -> 187.95 | Q29: =Q28 -> 189.76 | ... X29: =X28 -> 198.47 | Y29: =Y26 -> 372.78 | Z29: =Z26 -> 373.9 | AA29: =AA26 -> 374.81 | AB29: =AB26 -> 375.57 | AC29: =AC26 -> 377.42 | AD29: =AD26 -> 378.15 | AE29: =AE26 -> 381.35 | AF29: =AF26 -> 381 | ... AS29: =AS26 -> 386.45
A30: =A29 -> LOW_PMR1 | B30: ocgt_gas_h2_45 | C30: R/GJ | D30: 272 | E30: 272 | F30: 272 | G30: 272 | H30: 272 | I30: 272 | J30: =J28 -> 202.87 | K30: =K28 -> 197.88 | L30: =L28 -> 192.76 | M30: =M28 -> 189.04 | N30: =N28 -> 185 | O30: =O28 -> 186.51 | P30: =P28 -> 187.95 | Q30: =Q28 -> 189.76 | ... AC30: =AC28 -> 201.1 | AD30: =AD26 -> 378.15 | AE30: =AE26 -> 381.35 | AF30: =AF26 -> 381 | AG30: =AG26 -> 383.49 | AH30: =AH26 -> 384.2 | AI30: =AI26 -> 386.45 | AJ30: =AJ26 -> 386.45 | AK30: =AK26 -> 386.45 | ... AS30: =AS26 -> 386.45
A31: =A30 -> LOW_PMR1 | B31: ocgt_gas_h2_50 | C31: R/GJ | D31: 272 | E31: 272 | F31: 272 | G31: 272 | H31: 272 | I31: 272 | J31: =J28 -> 202.87 | K31: =K28 -> 197.88 | L31: =L28 -> 192.76 | M31: =M28 -> 189.04 | N31: =N28 -> 185 | O31: =O28 -> 186.51 | P31: =P28 -> 187.95 | Q31: =Q28 -> 189.76 | ... AH31: =AH28 -> 205.43 | AI31: =AI26 -> 386.45 | AJ31: =AJ26 -> 386.45 | AK31: =AK26 -> 386.45 | AL31: =AL26 -> 386.45 | AM31: =AM26 -> 386.45 | AN31: =AN26 -> 386.45 | AO31: =AO26 -> 386.45 | AP31: =AP26 -> 386.45 | ... AS31: =AS26 -> 386.45
A32: =A31 -> LOW_PMR1 | B32: ocgt_gas_h2_55 | C32: R/GJ | D32: 272 | E32: 272 | F32: 272 | G32: 272 | H32: 272 | I32: 272 | J32: =J30 -> 202.87 | K32: =K30 -> 197.88 | L32: =L30 -> 192.76 | M32: =M30 -> 189.04 | N32: =N30 -> 185 | O32: =O30 -> 186.51 | P32: =P30 -> 187.95 | Q32: =Q30 -> 189.76 | ... AB32: =AB30 -> 199.92 | AC32: =AC28 -> 201.1 | AD32: =AD28 -> 201.57 | AE32: =AE28 -> 203.61 | AF32: =AF28 -> 203.39 | AG32: =AG28 -> 204.98 | AH32: =AH28 -> 205.43 | AI32: =AI28 -> 206.87 | AJ32: =AJ28 -> 206.87 | ... AM32: =AM28 -> 206.87 | AN32: =AN30 -> 386.45 | AO32: =AO30 -> 386.45 | AP32: =AP30 -> 386.45 | AQ32: =AQ30 -> 386.45 | AR32: =AR30 -> 386.45 | AS32: =AS30 -> 386.45
A33: =A32 -> LOW_PMR1 | B33: ocgt_gas_h2_60 | C33: R/GJ | D33: 272 | E33: 272 | F33: 272 | G33: 272 | H33: 272 | I33: 272 | J33: =J30 -> 202.87 | K33: =K30 -> 197.88 | L33: =L30 -> 192.76 | M33: =M30 -> 189.04 | N33: =N30 -> 185 | O33: =O30 -> 186.51 | P33: =P30 -> 187.95 | Q33: =Q30 -> 189.76 | ... AB33: =AB30 -> 199.92 | AC33: =AC28 -> 201.1 | AD33: =AD28 -> 201.57 | AE33: =AE28 -> 203.61 | AF33: =AF28 -> 203.39 | AG33: =AG28 -> 204.98 | AH33: =AH28 -> 205.43 | AI33: =AI28 -> 206.87 | AJ33: =AJ28 -> 206.87 | ... AR33: =AR28 -> 206.87 | AS33: =AS26 -> 386.45
A34: =A33 -> LOW_PMR1 | B34: coal | C34: R/GJ | D34: 45.18 | E34: 45.18 | F34: 45.18 | G34: 45.18 | H34: 45.18 | I34: 45.18 | J34: 45.18 | K34: 45.18 | L34: 45.18 | M34: 45.18 | N34: 45.18 | O34: 45.18 | P34: 45.18 | Q34: 45.18 | R34: 45.18 | S34: 45.18 | T34: 45.18 | U34: 45.18 | V34: 45.18 | W34: 45.18 | X34: 45.18 | Y34: 45.18 | Z34: 45.18 | AA34: 45.18 | AB34: 45.18 | AC34: 45.18 | AD34: 45.18 | AE34: 45.18 | AF34: 45.18 | AG34: 45.18 | AH34: 45.18 | AI34: 45.18 | AJ34: =AI34 -> 45.18 | AK34: =AJ34 -> 45.18 | AL34: =AK34 -> 45.18 | AM34: =AL34 -> 45.18 | AN34: =AM34 -> 45.18 | AO34: =AN34 -> 45.18 | AP34: =AO34 -> 45.18 | AQ34: =AP34 -> 45.18 | ... AS34: =AR34 -> 45.18
A35: =A34 -> LOW_PMR1 | B35: nuclear | C35: R/GJ | D35: 18 | E35: 18 | F35: 18 | G35: 18 | H35: 18 | I35: 18 | J35: 18 | K35: 18 | L35: 18 | M35: 18 | N35: 18 | O35: 18 | P35: 18 | Q35: 18 | R35: 18 | S35: 18 | T35: 18 | U35: 18 | V35: 18 | W35: 18 | X35: 18 | Y35: 18 | Z35: 18 | AA35: 18 | AB35: 18 | AC35: 18 | AD35: 18 | AE35: 18 | AF35: 18 | AG35: 18 | AH35: 18 | AI35: 18 | AJ35: =AI35 -> 18 | AK35: =AJ35 -> 18 | AL35: =AK35 -> 18 | AM35: =AL35 -> 18 | AN35: =AM35 -> 18 | AO35: =AN35 -> 18 | AP35: =AO35 -> 18 | AQ35: =AP35 -> 18 | ... AS35: =AR35 -> 18
A36: =A35 -> LOW_PMR1 | B36: solar_csp | C36: R/GJ | D36: 0 | E36: 0 | F36: 0 | G36: 0 | H36: 0 | I36: 0 | J36: 0 | K36: 0 | L36: 0 | M36: 0 | N36: 0 | O36: 0 | P36: 0 | Q36: 0 | R36: 0 | S36: 0 | T36: 0 | U36: 0 | V36: 0 | W36: 0 | X36: 0 | Y36: 0 | Z36: 0 | AA36: 0 | AB36: 0 | AC36: 0 | AD36: 0 | AE36: 0 | AF36: 0 | AG36: 0 | AH36: 0 | AI36: 0 | AJ36: =AI36 -> 0 | AK36: =AJ36 -> 0 | AL36: =AK36 -> 0 | AM36: =AL36 -> 0 | AN36: =AM36 -> 0 | AO36: =AN36 -> 0 | AP36: =AO36 -> 0 | AQ36: =AP36 -> 0 | ... AS36: =AR36 -> 0
A37: =A36 -> LOW_PMR1 | B37: ccgt_steam | C37: R/GJ | D37: 0 | E37: 0 | F37: 0 | G37: 0 | H37: 0 | I37: 0 | J37: 0 | K37: 0 | L37: 0 | M37: 0 | N37: 0 | O37: 0 | P37: 0 | Q37: 0 | R37: 0 | S37: 0 | T37: 0 | U37: 0 | V37: 0 | W37: 0 | X37: 0 | Y37: 0 | Z37: 0 | AA37: 0 | AB37: 0 | AC37: 0 | AD37: 0 | AE37: 0 | AF37: 0 | AG37: 0 | AH37: 0 | AI37: 0 | AJ37: =AI37 -> 0 | AK37: =AJ37 -> 0 | AL37: =AK37 -> 0 | AM37: =AL37 -> 0 | AN37: =AM37 -> 0 | AO37: =AN37 -> 0 | AP37: =AO37 -> 0 | AQ37: =AP37 -> 0 | ... AS37: =AR37 -> 0
A38: IRP23 | B38: ocgt_diesel | C38: R/GJ | D38: 400.69668 | E38: 402.46947 | F38: 402.49144 | G38: 405.59713 | H38: 406.5107 | I38: 408.73353 | J38: 560 | K38: 560 | L38: 560 | M38: 560 | N38: 560 | O38: 560 | P38: 560 | Q38: 560 | R38: 560 | S38: 560 | T38: 560 | U38: 560 | V38: 560 | W38: 560 | X38: 560 | Y38: 560 | Z38: 560 | AA38: 560 | AB38: 560 | AC38: 560 | AD38: 560 | AE38: 560 | AF38: 560 | AG38: 560 | AH38: 560 | AI38: 560 | AJ38: 560 | AK38: 560 | AL38: 560 | AM38: 560 | AN38: 560 | AO38: 560 | AP38: 560 | AQ38: 560 | AR38: 560 | AS38: 560
A39: =A38 -> IRP23 | B39: ocgt_diesel_emg | C39: R/GJ | D39: 400.69668 | E39: 402.46947 | F39: 402.49144 | G39: 405.59713 | H39: 406.5107 | I39: 408.73353 | J39: 560 | K39: 560 | L39: 560 | M39: 560 | N39: 560 | O39: 560 | P39: 560 | Q39: 560 | R39: 560 | S39: 560 | T39: 560 | U39: 560 | V39: 560 | W39: 560 | X39: 560 | Y39: 560 | Z39: 560 | AA39: 560 | AB39: 560 | AC39: 560 | AD39: 560 | AE39: 560 | AF39: 560 | AG39: 560 | AH39: 560 | AI39: 560 | AJ39: 560 | AK39: 560 | AL39: 560 | AM39: 560 | AN39: 560 | AO39: 560 | AP39: 560 | AQ39: 560 | AR39: 560 | AS39: 560
A40: =A39 -> IRP23 | B40: ocgt_gas | C40: R/GJ | D40: 272 | E40: 272 | F40: 272 | G40: 272 | H40: 272 | I40: 272 | J40: 280 | K40: 280 | L40: 280 | M40: 280 | N40: 280 | O40: 280 | P40: 280 | Q40: 280 | R40: 280 | S40: 280 | T40: 280 | U40: 280 | V40: 280 | W40: 280 | X40: 280 | Y40: 280 | Z40: 280 | AA40: 280 | AB40: 280 | AC40: 280 | AD40: 280 | AE40: 280 | AF40: 280 | AG40: 280 | AH40: 280 | AI40: 280 | AJ40: 280 | AK40: 280 | AL40: 280 | AM40: 280 | AN40: 280 | AO40: 280 | AP40: 280 | AQ40: 280 | AR40: 280 | AS40: 280
...

Sheet green_NH3
A1: 2020.0467 | B1: 714.28399 | C1: 1394.413 | D1: $/t | E1: CV | F1: 0.0185 | G1: GJ/kg
A2: 2029.9994 | B2: 473.07826 | C2: 948.23786 | D2: $/t | F2: 18.7 | G2: ZAR:USD
A3: 2050.0066 | B3: 313.65872 | C3: 611.79273 | D3: $/t
A6: 2020 | B6: =B1/1000 -> 0.71428399 | C6: =C1/1000 -> 1.394413 | D6: $/kg | E6: =B6/$F$1*$F$2 -> 722.00598 | F6: =C6/$F$1*$F$2 -> 1409.4877 | G6: R/GJ | H6: =E6/0.278 -> 2597.1438 | I6: =H6/0.5 -> 5194.2877
A7: 2030 | B7: =B2/1000 -> 0.47307826 | C7: =C2/1000 -> 0.94823786 | D7: $/kg | E7: =B7/$F$1*$F$2 -> 478.19262 | F7: =C7/$F$1*$F$2 -> 958.48908 | G7: R/GJ | H7: =E7/0.278 -> 1720.1173 | I7: =H7/0.5 -> 3440.2347
A8: 2040 | B8: =0.5*B7+0.5*B9 -> 0.39336849 | C8: =0.5*C7+0.5*C9 -> 0.7800153 | D8: $/kg | E8: =B8/$F$1*$F$2 -> 397.62112 | F8: =C8/$F$1*$F$2 -> 788.4479 | G8: R/GJ | H8: =E8/0.278 -> 1430.2918 | I8: =H8/0.5 -> 2860.5836
A9: 2050 | B9: =B3/1000 -> 0.31365872 | C9: =C3/1000 -> 0.61179273 | D9: $/kg | E9: =B9/$F$1*$F$2 -> 317.04962 | F9: =C9/$F$1*$F$2 -> 618.40671 | G9: R/GJ | H9: =E9/0.278 -> 1140.4663 | I9: =H9/0.5 -> 2280.9325
A10: 2060
A12: https://www.irena.org/-/media/Files/IRENA/Agency/Publication/2022/May/IRENA_Innovation_Outlook_Ammonia_2022.pdf
P16: https://ora.ox.ac.uk/objects/uuid:475ce7d3-b6b8-42f6-8cb1-b33f56026689/files/r2801pg46c
K23: =600/0.278 -> 2158.2734 | L23: =K23/0.5 -> 4316.5468
H38: https://www.sciencedirect.com/science/article/abs/pii/S0306261920314549?via%3Dihub
G41: https://pubs.acs.org/doi/pdf/10.1021/acsenergylett.2c01615
A89: https://pubs.rsc.org/zh-tw/content/articlepdf/2024/ee/d3ee02951d

Sheet fuel_and_co2tax
A1: scenario | B1: station_name | C1: parameter | D1: 2019 | E1: 2020 | F1: =E1+1 -> 2021 | G1: =F1+1 -> 2022 | H1: =G1+1 -> 2023 | I1: =H1+1 -> 2024 | J1: =I1+1 -> 2025 | K1: =J1+1 -> 2026 | L1: =K1+1 -> 2027 | M1: =L1+1 -> 2028 | ... AS1: =AR1+1 -> 2060
A2: HIGH_FUEL | B2: ocgt_diesel | C2: R/GJ | J2: =extendable_generators!J2+74/1000*carbon_tax!D6 -> 431.86 | K2: =extendable_generators!K2+74/1000*carbon_tax!E6 -> 473.61 | L2: =extendable_generators!L2+74/1000*carbon_tax!F6 -> 515.29 | M2: =extendable_generators!M2+74/1000*carbon_tax!G6 -> 561.12 | N2: =extendable_generators!N2+74/1000*carbon_tax!H6 -> 608.33 | O2: =extendable_generators!O2+74/1000*carbon_tax!I6 -> 613.31 | P2: =extendable_generators!P2+74/1000*carbon_tax!J6 -> 650.548 | Q2: =extendable_generators!Q2+74/1000*carbon_tax!K6 -> 650.058 | ... AS2: =extendable_generators!AS2+74/1000*carbon_tax!AM6 -> 899.408
A3: HIGH_FUEL | B3: ocgt_diesel_emg | C3: R/GJ | J3: =extendable_generators!J3+74/1000*carbon_tax!D7 -> 429.64 | K3: =extendable_generators!K3+74/1000*carbon_tax!E7 -> 471.39 | L3: =extendable_generators!L3+74/1000*carbon_tax!F7 -> 513.07 | M3: =extendable_generators!M3+74/1000*carbon_tax!G7 -> 558.9 | N3: =extendable_generators!N3+74/1000*carbon_tax!H7 -> 606.11 | O3: =extendable_generators!O3+74/1000*carbon_tax!I7 -> 611.09 | P3: =extendable_generators!P3+74/1000*carbon_tax!J7 -> 616.36 | Q3: =extendable_generators!Q3+74/1000*carbon_tax!K7 -> 615.87 | ... AS3: =extendable_generators!AS3+74/1000*carbon_tax!AM7 -> 655.8
A4: HIGH_FUEL | B4: ocgt_gas | C4: R/GJ | J4: =extendable_generators!J4+0.069*carbon_tax!D6 -> 246.74 | K4: =extendable_generators!K4+0.069*carbon_tax!E6 -> 273.4 | L4: =extendable_generators!L4+0.069*carbon_tax!F6 -> 300.02 | M4: =extendable_generators!M4+0.069*carbon_tax!G6 -> 329.29 | N4: =extendable_generators!N4+0.069*carbon_tax!H6 -> 359.44 | O4: =extendable_generators!O4+0.069*carbon_tax!I6 -> 362.62 | P4: =extendable_generators!P4+0.069*carbon_tax!J6 -> 395.798 | Q4: =extendable_generators!Q4+0.069*carbon_tax!K6 -> 395.488 | ... AS4: =extendable_generators!AS4+0.069*carbon_tax!AM6 -> 616.248
A5: HIGH_FUEL | B5: ocgt_gas_h2_40 | C5: R/GJ
A6: HIGH_FUEL | B6: ocgt_gas_h2_45 | C6: R/GJ
A7: HIGH_FUEL | B7: ocgt_gas_h2_50 | C7: R/GJ
A8: HIGH_FUEL | B8: ocgt_gas_h2_55 | C8: R/GJ
A9: HIGH_FUEL | B9: ocgt_gas_h2_60 | C9: R/GJ
A10: HIGH_FUEL | B10: ccgt_steam | C10: R/GJ
A11: HIGH_FUEL | B11: biomass_forestry | C11: R/GJ
A12: HIGH_FUEL | B12: biomass_landfill_gas | C12: R/GJ
A13: HIGH_FUEL | B13: biomass_biogas | C13: R/GJ
A14: HIGH_FUEL | B14: biomass_MSW | C14: R/GJ
A15: HIGH_FUEL | B15: coal | C15: R/GJ
A16: HIGH_FUEL | B16: nuclear | C16: R/GJ
... A34: MED_FUEL | B34: ccgt_steam | C34: R/GJ
A35: LOW_FUEL | B35: ocgt_diesel | C35: R/GJ | J35: =extendable_generators!J26+0.074*carbon_tax!C4 -> 382.41 | K35: =extendable_generators!K26+0.074*carbon_tax!D4 -> 374.59 | L35: =extendable_generators!L26+0.074*carbon_tax!E4 -> 366.57 | M35: =extendable_generators!M26+0.074*carbon_tax!F4 -> 360.76 | N35: =extendable_generators!N26+0.074*carbon_tax!G4 -> 354.42 | O35: =extendable_generators!O26+0.074*carbon_tax!H4 -> 356.79 | P35: =extendable_generators!P26+0.074*carbon_tax!I4 -> 359.05 | Q35: =extendable_generators!Q26+0.074*carbon_tax!J4 -> 369.0617 | ... AS35: =extendable_generators!AS26+0.074*carbon_tax!AL4 -> 539.35028
A36: LOW_FUEL | B36: ocgt_diesel_emg | C36: R/GJ
A37: LOW_FUEL | B37: ocgt_gas | C37: R/GJ
A38: LOW_FUEL | B38: ocgt_gas_h2_40 | C38: R/GJ
A39: LOW_FUEL | B39: ocgt_gas_h2_45 | C39: R/GJ
A40: LOW_FUEL | B40: ocgt_gas_h2_50 | C40: R/GJ
A41: LOW_FUEL | B41: ocgt_gas_h2_55 | C41: R/GJ
A42: LOW_FUEL | B42: ocgt_gas_h2_60 | C42: R/GJ
A43: LOW_FUEL | B43: biomass_forestry | C43: R/GJ
A44: LOW_FUEL | B44: biomass_landfill_gas | C44: R/GJ
A45: LOW_FUEL | B45: biomass_biogas | C45: R/GJ
A46: LOW_FUEL | B46: biomass_MSW | C46: R/GJ
A47: LOW_FUEL | B47: coal | C47: R/GJ
... A51: IRP23 | B51: ocgt_diesel | C51: R/GJ
A52: =A51 -> IRP23 | B52: ocgt_diesel_emg | C52: R/GJ
A53: =A52 -> IRP23 | B53: ocgt_gas | C53: R/GJ
A54: =A53 -> IRP23 | B54: ocgt_gas_h2_40 | C54: R/GJ
A55: =A54 -> IRP23 | B55: ocgt_gas_h2_45 | C55: R/GJ
A56: =A55 -> IRP23 | B56: ocgt_gas_h2_50 | C56: R/GJ
A57: =A56 -> IRP23 | B57: biomass_forestry | C57: R/GJ
A58: =A57 -> IRP23 | B58: biomass_landfill_gas | C58: R/GJ
A59: =A58 -> IRP23 | B59: biomass_biogas | C59: R/GJ
A60: =A59 -> IRP23 | B60: biomass_MSW | C60: R/GJ
...

Sheet carbon_tax
A1: scenario | B1: units | C1: 2024 | D1: 2025 | E1: =D1+1 -> 2026 | F1: =E1+1 -> 2027 | G1: =F1+1 -> 2028 | H1: =G1+1 -> 2029 | I1: =H1+1 -> 2030 | J1: =I1+1 -> 2031 | K1: =J1+1 -> 2032 | L1: =K1+1 -> 2033 | ... AM1: =AL1+1 -> 2060
A2: none | B2: R/tCO2e | C2: 0 | D2: =C2 -> 0 | E2: =D2 -> 0 | F2: =E2 -> 0 | G2: =F2 -> 0 | H2: =G2 -> 0 | I2: =H2 -> 0 | J2: =I2 -> 0 | K2: =J2 -> 0 | ... AM2: =AL2 -> 0
A3: IRP23 | B3: R/tCO2e | C3: 0 | D3: 0 | E3: 308 | F3: 347 | G3: 385 | H3: 424 | I3: 462 | J3: =($S$3-$I$3)/10+I3 -> 507.95 | K3: =($S$3-$I$3)/10+J3 -> 553.9 | L3: =($S$3-$I$3)/10+K3 -> 599.85 | M3: =($S$3-$I$3)/10+L3 -> 645.8 | N3: =($S$3-$I$3)/10+M3 -> 691.75 | O3: =($S$3-$I$3)/10+N3 -> 737.7 | P3: =($S$3-$I$3)/10+O3 -> 783.65 | Q3: =($S$3-$I$3)/10+P3 -> 829.6 | R3: =($S$3-$I$3)/10+Q3 -> 875.55 | S3: =50*18.43 -> 921.5 | T3: =($AC$3-$S$3)/10+S3 -> 1013.65 | U3: =($AC$3-$S$3)/10+T3 -> 1105.8 | V3: =($AC$3-$S$3)/10+U3 -> 1197.95 | W3: =($AC$3-$S$3)/10+V3 -> 1290.1 | X3: =($AC$3-$S$3)/10+W3 -> 1382.25 | Y3: =($AC$3-$S$3)/10+X3 -> 1474.4 | Z3: =($AC$3-$S$3)/10+Y3 -> 1566.55 | AA3: =($AC$3-$S$3)/10+Z3 -> 1658.7 | AB3: =($AC$3-$S$3)/10+AA3 -> 1750.85 | AC3: =100*18.43 -> 1843 | AD3: =+($AC$3-$S$3)/10+AC3 -> 1935.15 | AE3: =+($AC$3-$S$3)/10+AD3 -> 2027.3 | AF3: =+($AC$3-$S$3)/10+AE3 -> 2119.45 | AG3: =+($AC$3-$S$3)/10+AF3 -> 2211.6 | AH3: =+($AC$3-$S$3)/10+AG3 -> 2303.75 | AI3: =+($AC$3-$S$3)/10+AH3 -> 2395.9 | AJ3: =+($AC$3-$S$3)/10+AI3 -> 2488.05 | AK3: =+($AC$3-$S$3)/10+AJ3 -> 2580.2 | ... AM3: =+($AC$3-$S$3)/10+AL3 -> 2764.5
A4: LOW | B4: R/tCO2e | C4: 30 | D4: 30 | E4: 30 | F4: 30 | G4: 30 | H4: 30 | I4: 30 | J4: 127.05 | K4: 138.6 | L4: 150.15 | M4: 161.7 | N4: 173.25 | O4: 230.08 | P4: 292.57 | Q4: 360.72 | R4: 434.53 | S4: 514 | T4: 599.13 | U4: 689.92 | V4: 786.37 | W4: 888.48 | X4: 996.25 | Y4: 1109.68 | Z4: 1183.26 | AA4: 1256.84 | AB4: 1330.42 | AC4: 1404 | AD4: 1477.58 | AE4: 1551.16 | AF4: 1624.74 | AG4: 1698.32 | AH4: 1771.9 | AI4: 1845.48 | AJ4: 1919.06 | AK4: 1992.64 | AL4: 2066.22 | AM4: 2139.8
A5: BASE | B5: R/tCO2e | C5: 30 | D5: 30 | E5: 30 | F5: 30 | G5: 30 | H5: 30 | I5: 30 | J5: 242.55 | K5: 254.1 | L5: 265.65 | M5: 277.2 | N5: 288.75 | O5: 373.88 | P5: 464.67 | Q5: 561.12 | R5: 663.23 | S5: 771 | T5: 884.43 | U5: 1003.52 | V5: 1128.27 | W5: 1258.68 | X5: 1394.75 | Y5: 1536.48 | Z5: 1638.36 | AA5: 1740.24 | AB5: 1842.12 | AC5: 1944 | AD5: 2045.88 | AE5: 2147.76 | AF5: 2249.64 | AG5: 2351.52 | AH5: 2453.4 | AI5: 2555.28 | AJ5: 2657.16 | AK5: 2759.04 | AL5: 2860.92 | AM5: 2962.8
A6: HIGH | B6: R/tCO2e | C6: 30 | D6: 30 | E6: 30 | F6: 30 | G6: 30 | H6: 30 | I6: 30 | J6: 462 | K6: 462 | L6: 462 | M6: 462 | N6: 462 | O6: 575.2 | P6: 688.4 | Q6: 801.6 | R6: 914.8 | S6: 1028 | T6: 1141.2 | U6: 1254.4 | V6: 1367.6 | W6: 1480.8 | X6: 1594 | Y6: 1707.2 | Z6: 1820.4 | AA6: 1933.6 | AB6: 2046.8 | AC6: 2160 | AD6: 2273.2 | AE6: 2386.4 | AF6: 2499.6 | AG6: 2612.8 | AH6: 2726 | AI6: 2839.2 | AJ6: 2952.4 | AK6: 3065.6 | AL6: 3178.8 | AM6: 3292
A8: emissions
